2024-06-07 10:54:17 AM | ERROR | An Error occured while logging in.
2024-06-07 11:14:36 AM | ERROR | Exception in start_session: ('Connection aborted.', ConnectionResetError(10054, 'An existing connection was forcibly closed by the remote host', None, 10054, None))
2024-06-07 11:30:40 AM | DEBUG | Exception in track_message_recive: 'FacebookAutomation' object has no attribute 'message_recive'
2024-06-07 11:30:41 AM | DEBUG | Exception in track_message_recive: Message: stale element reference: stale element not found
  (Session info: chrome=117.0.5938.92); For documentation on this error, please visit: https://www.selenium.dev/documentation/webdriver/troubleshooting/errors#stale-element-reference-exception
Stacktrace:
	GetHandleVerifier [0x00007FF61F1F78A2+54818]
	(No symbol) [0x00007FF61F166AD2]
	(No symbol) [0x00007FF61F01DA3B]
	(No symbol) [0x00007FF61F02246D]
	(No symbol) [0x00007FF61F023F5F]
	(No symbol) [0x00007FF61F024050]
	(No symbol) [0x00007FF61F05E184]
	(No symbol) [0x00007FF61F05E67C]
	(No symbol) [0x00007FF61F05544C]
	(No symbol) [0x00007FF61F07EAEF]
	(No symbol) [0x00007FF61F055036]
	(No symbol) [0x00007FF61F07ECC0]
	(No symbol) [0x00007FF61F0975A2]
	(No symbol) [0x00007FF61F07E883]
	(No symbol) [0x00007FF61F053691]
	(No symbol) [0x00007FF61F0548D4]
	GetHandleVerifier [0x00007FF61F55B9A2+3610402]
	GetHandleVerifier [0x00007FF61F5B1870+3962352]
	GetHandleVerifier [0x00007FF61F5A9D5F+3930847]
	GetHandleVerifier [0x00007FF61F293656+693206]
	(No symbol) [0x00007FF61F171638]
	(No symbol) [0x00007FF61F16D944]
	(No symbol) [0x00007FF61F16DA72]
	(No symbol) [0x00007FF61F15E123]
	BaseThreadInitThunk [0x00007FF9095E7344+20]
	RtlUserThreadStart [0x00007FF90A4026B1+33]

2024-06-07 11:30:42 AM | DEBUG | Exception in track_message_recive: Message: stale element reference: stale element not found
  (Session info: chrome=117.0.5938.92); For documentation on this error, please visit: https://www.selenium.dev/documentation/webdriver/troubleshooting/errors#stale-element-reference-exception
Stacktrace:
	GetHandleVerifier [0x00007FF61F1F78A2+54818]
	(No symbol) [0x00007FF61F166AD2]
	(No symbol) [0x00007FF61F01DA3B]
	(No symbol) [0x00007FF61F02246D]
	(No symbol) [0x00007FF61F023F5F]
	(No symbol) [0x00007FF61F024050]
	(No symbol) [0x00007FF61F05E184]
	(No symbol) [0x00007FF61F05E67C]
	(No symbol) [0x00007FF61F05544C]
	(No symbol) [0x00007FF61F07EAEF]
	(No symbol) [0x00007FF61F055036]
	(No symbol) [0x00007FF61F07ECC0]
	(No symbol) [0x00007FF61F0975A2]
	(No symbol) [0x00007FF61F07E883]
	(No symbol) [0x00007FF61F053691]
	(No symbol) [0x00007FF61F0548D4]
	GetHandleVerifier [0x00007FF61F55B9A2+3610402]
	GetHandleVerifier [0x00007FF61F5B1870+3962352]
	GetHandleVerifier [0x00007FF61F5A9D5F+3930847]
	GetHandleVerifier [0x00007FF61F293656+693206]
	(No symbol) [0x00007FF61F171638]
	(No symbol) [0x00007FF61F16D944]
	(No symbol) [0x00007FF61F16DA72]
	(No symbol) [0x00007FF61F15E123]
	BaseThreadInitThunk [0x00007FF9095E7344+20]
	RtlUserThreadStart [0x00007FF90A4026B1+33]

2024-06-07 11:30:44 AM | DEBUG | Exception in track_message_recive: 'FacebookAutomation' object has no attribute 'message_recive'
2024-06-07 11:30:46 AM | DEBUG | Exception in track_message_recive: 'FacebookAutomation' object has no attribute 'message_recive'
2024-06-07 11:30:48 AM | DEBUG | Exception in track_message_recive: 'FacebookAutomation' object has no attribute 'message_recive'
2024-06-07 11:30:50 AM | DEBUG | Exception in track_message_recive: 'FacebookAutomation' object has no attribute 'message_recive'
2024-06-07 11:30:53 AM | DEBUG | Exception in track_message_recive: 'FacebookAutomation' object has no attribute 'message_recive'
2024-06-07 11:30:55 AM | DEBUG | Exception in track_message_recive: 'FacebookAutomation' object has no attribute 'message_recive'
2024-06-07 11:30:57 AM | DEBUG | Exception in track_message_recive: 'FacebookAutomation' object has no attribute 'message_recive'
2024-06-07 11:30:59 AM | DEBUG | Exception in track_message_recive: 'FacebookAutomation' object has no attribute 'message_recive'
2024-06-07 11:31:01 AM | DEBUG | Exception in track_message_recive: 'FacebookAutomation' object has no attribute 'message_recive'
2024-06-07 11:31:03 AM | DEBUG | Exception in track_message_recive: 'FacebookAutomation' object has no attribute 'message_recive'
2024-06-07 11:31:05 AM | DEBUG | Exception in track_message_recive: 'FacebookAutomation' object has no attribute 'message_recive'
2024-06-07 11:31:07 AM | DEBUG | Exception in track_message_recive: 'FacebookAutomation' object has no attribute 'message_recive'
2024-06-07 11:31:09 AM | DEBUG | Exception in track_message_recive: 'FacebookAutomation' object has no attribute 'message_recive'
2024-06-07 11:31:11 AM | DEBUG | Exception in track_message_recive: 'FacebookAutomation' object has no attribute 'message_recive'
2024-06-07 11:31:14 AM | DEBUG | Exception in track_message_recive: 'FacebookAutomation' object has no attribute 'message_recive'
2024-06-07 11:31:16 AM | DEBUG | Exception in track_message_recive: 'FacebookAutomation' object has no attribute 'message_recive'
2024-06-07 11:31:18 AM | DEBUG | Exception in track_message_recive: 'FacebookAutomation' object has no attribute 'message_recive'
2024-06-07 11:31:20 AM | DEBUG | Exception in track_message_recive: 'FacebookAutomation' object has no attribute 'message_recive'
2024-06-07 11:31:22 AM | DEBUG | Exception in track_message_recive: 'FacebookAutomation' object has no attribute 'message_recive'
2024-06-07 11:31:24 AM | DEBUG | Exception in track_message_recive: 'FacebookAutomation' object has no attribute 'message_recive'
2024-06-07 11:31:26 AM | DEBUG | Exception in track_message_recive: 'FacebookAutomation' object has no attribute 'message_recive'
2024-06-07 11:31:28 AM | DEBUG | Exception in track_message_recive: 'FacebookAutomation' object has no attribute 'message_recive'
2024-06-07 11:31:30 AM | DEBUG | Exception in track_message_recive: 'FacebookAutomation' object has no attribute 'message_recive'
2024-06-07 11:31:33 AM | DEBUG | Exception in track_message_recive: 'FacebookAutomation' object has no attribute 'message_recive'
2024-06-07 11:31:35 AM | DEBUG | Exception in track_message_recive: 'FacebookAutomation' object has no attribute 'message_recive'
2024-06-07 11:31:37 AM | DEBUG | Exception in track_message_recive: 'FacebookAutomation' object has no attribute 'message_recive'
2024-06-07 11:31:39 AM | DEBUG | Exception in track_message_recive: 'FacebookAutomation' object has no attribute 'message_recive'
2024-06-07 11:31:41 AM | DEBUG | Exception in track_message_recive: 'FacebookAutomation' object has no attribute 'message_recive'
2024-06-07 11:31:43 AM | DEBUG | Exception in track_message_recive: 'FacebookAutomation' object has no attribute 'message_recive'
2024-06-07 11:31:45 AM | DEBUG | Exception in track_message_recive: 'FacebookAutomation' object has no attribute 'message_recive'
2024-06-07 11:31:47 AM | DEBUG | Exception in track_message_recive: 'FacebookAutomation' object has no attribute 'message_recive'
2024-06-07 11:31:49 AM | DEBUG | Exception in track_message_recive: 'FacebookAutomation' object has no attribute 'message_recive'
2024-06-07 11:31:51 AM | DEBUG | Exception in track_message_recive: 'FacebookAutomation' object has no attribute 'message_recive'
2024-06-07 11:31:54 AM | DEBUG | Exception in track_message_recive: 'FacebookAutomation' object has no attribute 'message_recive'
2024-06-07 11:31:56 AM | DEBUG | Exception in track_message_recive: 'FacebookAutomation' object has no attribute 'message_recive'
2024-06-07 11:31:58 AM | DEBUG | Exception in track_message_recive: 'FacebookAutomation' object has no attribute 'message_recive'
2024-06-07 11:32:00 AM | DEBUG | Exception in track_message_recive: 'FacebookAutomation' object has no attribute 'message_recive'
2024-06-07 11:35:29 AM | ERROR | Exception in start_session: Element not found
2024-06-07 11:53:28 AM | DEBUG | Exception in track_message_recive: Message: stale element reference: stale element not found
  (Session info: headless chrome=117.0.5938.92); For documentation on this error, please visit: https://www.selenium.dev/documentation/webdriver/troubleshooting/errors#stale-element-reference-exception
Stacktrace:
	GetHandleVerifier [0x00007FF61F1F78A2+54818]
	(No symbol) [0x00007FF61F166AD2]
	(No symbol) [0x00007FF61F01DA3B]
	(No symbol) [0x00007FF61F02246D]
	(No symbol) [0x00007FF61F023F5F]
	(No symbol) [0x00007FF61F024050]
	(No symbol) [0x00007FF61F05E184]
	(No symbol) [0x00007FF61F05E67C]
	(No symbol) [0x00007FF61F05544C]
	(No symbol) [0x00007FF61F07EAEF]
	(No symbol) [0x00007FF61F055036]
	(No symbol) [0x00007FF61F07ECC0]
	(No symbol) [0x00007FF61F0975A2]
	(No symbol) [0x00007FF61F07E883]
	(No symbol) [0x00007FF61F053691]
	(No symbol) [0x00007FF61F0548D4]
	GetHandleVerifier [0x00007FF61F55B9A2+3610402]
	GetHandleVerifier [0x00007FF61F5B1870+3962352]
	GetHandleVerifier [0x00007FF61F5A9D5F+3930847]
	GetHandleVerifier [0x00007FF61F293656+693206]
	(No symbol) [0x00007FF61F171638]
	(No symbol) [0x00007FF61F16D944]
	(No symbol) [0x00007FF61F16DA72]
	(No symbol) [0x00007FF61F15E123]
	BaseThreadInitThunk [0x00007FF9095E7344+20]
	RtlUserThreadStart [0x00007FF90A4026B1+33]

2024-06-07 11:53:29 AM | DEBUG | Exception in track_message_recive: Message: stale element reference: stale element not found
  (Session info: headless chrome=117.0.5938.92); For documentation on this error, please visit: https://www.selenium.dev/documentation/webdriver/troubleshooting/errors#stale-element-reference-exception
Stacktrace:
	GetHandleVerifier [0x00007FF61F1F78A2+54818]
	(No symbol) [0x00007FF61F166AD2]
	(No symbol) [0x00007FF61F01DA3B]
	(No symbol) [0x00007FF61F02246D]
	(No symbol) [0x00007FF61F023F5F]
	(No symbol) [0x00007FF61F024050]
	(No symbol) [0x00007FF61F05E184]
	(No symbol) [0x00007FF61F05E67C]
	(No symbol) [0x00007FF61F05544C]
	(No symbol) [0x00007FF61F07EAEF]
	(No symbol) [0x00007FF61F055036]
	(No symbol) [0x00007FF61F07ECC0]
	(No symbol) [0x00007FF61F0975A2]
	(No symbol) [0x00007FF61F07E883]
	(No symbol) [0x00007FF61F053691]
	(No symbol) [0x00007FF61F0548D4]
	GetHandleVerifier [0x00007FF61F55B9A2+3610402]
	GetHandleVerifier [0x00007FF61F5B1870+3962352]
	GetHandleVerifier [0x00007FF61F5A9D5F+3930847]
	GetHandleVerifier [0x00007FF61F293656+693206]
	(No symbol) [0x00007FF61F171638]
	(No symbol) [0x00007FF61F16D944]
	(No symbol) [0x00007FF61F16DA72]
	(No symbol) [0x00007FF61F15E123]
	BaseThreadInitThunk [0x00007FF9095E7344+20]
	RtlUserThreadStart [0x00007FF90A4026B1+33]

2024-06-07 11:53:29 AM | DEBUG | Exception in track_message_recive: Message: stale element reference: stale element not found
  (Session info: headless chrome=117.0.5938.92); For documentation on this error, please visit: https://www.selenium.dev/documentation/webdriver/troubleshooting/errors#stale-element-reference-exception
Stacktrace:
	GetHandleVerifier [0x00007FF61F1F78A2+54818]
	(No symbol) [0x00007FF61F166AD2]
	(No symbol) [0x00007FF61F01DA3B]
	(No symbol) [0x00007FF61F02246D]
	(No symbol) [0x00007FF61F023F5F]
	(No symbol) [0x00007FF61F024050]
	(No symbol) [0x00007FF61F05E184]
	(No symbol) [0x00007FF61F05E67C]
	(No symbol) [0x00007FF61F05544C]
	(No symbol) [0x00007FF61F07EAEF]
	(No symbol) [0x00007FF61F055036]
	(No symbol) [0x00007FF61F07ECC0]
	(No symbol) [0x00007FF61F0975A2]
	(No symbol) [0x00007FF61F07E883]
	(No symbol) [0x00007FF61F053691]
	(No symbol) [0x00007FF61F0548D4]
	GetHandleVerifier [0x00007FF61F55B9A2+3610402]
	GetHandleVerifier [0x00007FF61F5B1870+3962352]
	GetHandleVerifier [0x00007FF61F5A9D5F+3930847]
	GetHandleVerifier [0x00007FF61F293656+693206]
	(No symbol) [0x00007FF61F171638]
	(No symbol) [0x00007FF61F16D944]
	(No symbol) [0x00007FF61F16DA72]
	(No symbol) [0x00007FF61F15E123]
	BaseThreadInitThunk [0x00007FF9095E7344+20]
	RtlUserThreadStart [0x00007FF90A4026B1+33]

2024-06-07 12:01:11 PM | ERROR | Exception in start_session: Message: unknown error: net::ERR_NAME_NOT_RESOLVED
  (Session info: headless chrome=117.0.5938.92)
Stacktrace:
	GetHandleVerifier [0x00007FF61F1F78A2+54818]
	(No symbol) [0x00007FF61F166AD2]
	(No symbol) [0x00007FF61F01DA3B]
	(No symbol) [0x00007FF61F019853]
	(No symbol) [0x00007FF61F00CB9C]
	(No symbol) [0x00007FF61F00DDF7]
	(No symbol) [0x00007FF61F00CF95]
	(No symbol) [0x00007FF61F00C00E]
	(No symbol) [0x00007FF61F00BFB3]
	(No symbol) [0x00007FF61F00A82E]
	(No symbol) [0x00007FF61F00B123]
	(No symbol) [0x00007FF61F01FE4F]
	(No symbol) [0x00007FF61F097917]
	(No symbol) [0x00007FF61F07EAAA]
	(No symbol) [0x00007FF61F0975A2]
	(No symbol) [0x00007FF61F07E883]
	(No symbol) [0x00007FF61F053691]
	(No symbol) [0x00007FF61F0548D4]
	GetHandleVerifier [0x00007FF61F55B9A2+3610402]
	GetHandleVerifier [0x00007FF61F5B1870+3962352]
	GetHandleVerifier [0x00007FF61F5A9D5F+3930847]
	GetHandleVerifier [0x00007FF61F293656+693206]
	(No symbol) [0x00007FF61F171638]
	(No symbol) [0x00007FF61F16D944]
	(No symbol) [0x00007FF61F16DA72]
	(No symbol) [0x00007FF61F15E123]
	BaseThreadInitThunk [0x00007FF9095E7344+20]
	RtlUserThreadStart [0x00007FF90A4026B1+33]

2024-06-07 12:01:12 PM | ERROR | Exception in start_session: Message: unknown error: net::ERR_NAME_NOT_RESOLVED
  (Session info: headless chrome=117.0.5938.92)
Stacktrace:
	GetHandleVerifier [0x00007FF61F1F78A2+54818]
	(No symbol) [0x00007FF61F166AD2]
	(No symbol) [0x00007FF61F01DA3B]
	(No symbol) [0x00007FF61F019853]
	(No symbol) [0x00007FF61F00CB9C]
	(No symbol) [0x00007FF61F00DDF7]
	(No symbol) [0x00007FF61F00CF95]
	(No symbol) [0x00007FF61F00C00E]
	(No symbol) [0x00007FF61F00BFB3]
	(No symbol) [0x00007FF61F00A82E]
	(No symbol) [0x00007FF61F00B123]
	(No symbol) [0x00007FF61F01FE4F]
	(No symbol) [0x00007FF61F097917]
	(No symbol) [0x00007FF61F07EAAA]
	(No symbol) [0x00007FF61F0975A2]
	(No symbol) [0x00007FF61F07E883]
	(No symbol) [0x00007FF61F053691]
	(No symbol) [0x00007FF61F0548D4]
	GetHandleVerifier [0x00007FF61F55B9A2+3610402]
	GetHandleVerifier [0x00007FF61F5B1870+3962352]
	GetHandleVerifier [0x00007FF61F5A9D5F+3930847]
	GetHandleVerifier [0x00007FF61F293656+693206]
	(No symbol) [0x00007FF61F171638]
	(No symbol) [0x00007FF61F16D944]
	(No symbol) [0x00007FF61F16DA72]
	(No symbol) [0x00007FF61F15E123]
	BaseThreadInitThunk [0x00007FF9095E7344+20]
	RtlUserThreadStart [0x00007FF90A4026B1+33]

2024-06-07 12:02:44 PM | ERROR | Exception in screenshot: HTTPConnectionPool(host='localhost', port=58528): Max retries exceeded with url: /session/52ea1e7d3c6e0b7fe8b1f62e1392da08/screenshot (Caused by NewConnectionError('<urllib3.connection.HTTPConnection object at 0x0000029377A532B0>: Failed to establish a new connection: [WinError 10061] No connection could be made because the target machine actively refused it'))
2024-06-07 12:04:03 PM | ERROR | Exception in screenshot: HTTPConnectionPool(host='localhost', port=58528): Max retries exceeded with url: /session/52ea1e7d3c6e0b7fe8b1f62e1392da08/screenshot (Caused by NewConnectionError('<urllib3.connection.HTTPConnection object at 0x0000029377A539D0>: Failed to establish a new connection: [WinError 10061] No connection could be made because the target machine actively refused it'))
2024-06-25 11:45:34 AM | DEBUG | Exception in start_automation: Message: stale element reference: stale element not found
  (Session info: chrome=117.0.5938.92); For documentation on this error, please visit: https://www.selenium.dev/documentation/webdriver/troubleshooting/errors#stale-element-reference-exception
Stacktrace:
	GetHandleVerifier [0x00007FF64AA278A2+54818]
	(No symbol) [0x00007FF64A996AD2]
	(No symbol) [0x00007FF64A84DA3B]
	(No symbol) [0x00007FF64A85246D]
	(No symbol) [0x00007FF64A853F5F]
	(No symbol) [0x00007FF64A854050]
	(No symbol) [0x00007FF64A88E184]
	(No symbol) [0x00007FF64A88E67C]
	(No symbol) [0x00007FF64A88544C]
	(No symbol) [0x00007FF64A8AEAEF]
	(No symbol) [0x00007FF64A885036]
	(No symbol) [0x00007FF64A8AECC0]
	(No symbol) [0x00007FF64A8C75A2]
	(No symbol) [0x00007FF64A8AE883]
	(No symbol) [0x00007FF64A883691]
	(No symbol) [0x00007FF64A8848D4]
	GetHandleVerifier [0x00007FF64AD8B9A2+3610402]
	GetHandleVerifier [0x00007FF64ADE1870+3962352]
	GetHandleVerifier [0x00007FF64ADD9D5F+3930847]
	GetHandleVerifier [0x00007FF64AAC3656+693206]
	(No symbol) [0x00007FF64A9A1638]
	(No symbol) [0x00007FF64A99D944]
	(No symbol) [0x00007FF64A99DA72]
	(No symbol) [0x00007FF64A98E123]
	BaseThreadInitThunk [0x00007FF9E8827344+20]
	RtlUserThreadStart [0x00007FF9E91DCC91+33]

2024-06-25 11:45:34 AM | DEBUG | Exception in start_automation: Message: stale element reference: stale element not found
  (Session info: chrome=117.0.5938.92); For documentation on this error, please visit: https://www.selenium.dev/documentation/webdriver/troubleshooting/errors#stale-element-reference-exception
Stacktrace:
	GetHandleVerifier [0x00007FF64AA278A2+54818]
	(No symbol) [0x00007FF64A996AD2]
	(No symbol) [0x00007FF64A84DA3B]
	(No symbol) [0x00007FF64A85246D]
	(No symbol) [0x00007FF64A853F5F]
	(No symbol) [0x00007FF64A854050]
	(No symbol) [0x00007FF64A88E184]
	(No symbol) [0x00007FF64A88E67C]
	(No symbol) [0x00007FF64A88544C]
	(No symbol) [0x00007FF64A8AEAEF]
	(No symbol) [0x00007FF64A885036]
	(No symbol) [0x00007FF64A8AECC0]
	(No symbol) [0x00007FF64A8C75A2]
	(No symbol) [0x00007FF64A8AE883]
	(No symbol) [0x00007FF64A883691]
	(No symbol) [0x00007FF64A8848D4]
	GetHandleVerifier [0x00007FF64AD8B9A2+3610402]
	GetHandleVerifier [0x00007FF64ADE1870+3962352]
	GetHandleVerifier [0x00007FF64ADD9D5F+3930847]
	GetHandleVerifier [0x00007FF64AAC3656+693206]
	(No symbol) [0x00007FF64A9A1638]
	(No symbol) [0x00007FF64A99D944]
	(No symbol) [0x00007FF64A99DA72]
	(No symbol) [0x00007FF64A98E123]
	BaseThreadInitThunk [0x00007FF9E8827344+20]
	RtlUserThreadStart [0x00007FF9E91DCC91+33]

2024-06-25 11:45:34 AM | DEBUG | Exception in start_automation: Message: stale element reference: stale element not found
  (Session info: chrome=117.0.5938.92); For documentation on this error, please visit: https://www.selenium.dev/documentation/webdriver/troubleshooting/errors#stale-element-reference-exception
Stacktrace:
	GetHandleVerifier [0x00007FF64AA278A2+54818]
	(No symbol) [0x00007FF64A996AD2]
	(No symbol) [0x00007FF64A84DA3B]
	(No symbol) [0x00007FF64A85246D]
	(No symbol) [0x00007FF64A853F5F]
	(No symbol) [0x00007FF64A854050]
	(No symbol) [0x00007FF64A88E184]
	(No symbol) [0x00007FF64A88E67C]
	(No symbol) [0x00007FF64A88544C]
	(No symbol) [0x00007FF64A8AEAEF]
	(No symbol) [0x00007FF64A885036]
	(No symbol) [0x00007FF64A8AECC0]
	(No symbol) [0x00007FF64A8C75A2]
	(No symbol) [0x00007FF64A8AE883]
	(No symbol) [0x00007FF64A883691]
	(No symbol) [0x00007FF64A8848D4]
	GetHandleVerifier [0x00007FF64AD8B9A2+3610402]
	GetHandleVerifier [0x00007FF64ADE1870+3962352]
	GetHandleVerifier [0x00007FF64ADD9D5F+3930847]
	GetHandleVerifier [0x00007FF64AAC3656+693206]
	(No symbol) [0x00007FF64A9A1638]
	(No symbol) [0x00007FF64A99D944]
	(No symbol) [0x00007FF64A99DA72]
	(No symbol) [0x00007FF64A98E123]
	BaseThreadInitThunk [0x00007FF9E8827344+20]
	RtlUserThreadStart [0x00007FF9E91DCC91+33]

2024-06-25 11:46:12 AM | ERROR | Exception in start_session: Element not found
2024-06-25 14:43:17 PM | ERROR | Exception in start_session: Element not found
2024-06-25 14:46:35 PM | DEBUG | Exception in start_automation: Message: stale element reference: stale element not found
  (Session info: chrome=117.0.5938.92); For documentation on this error, please visit: https://www.selenium.dev/documentation/webdriver/troubleshooting/errors#stale-element-reference-exception
Stacktrace:
	GetHandleVerifier [0x00007FF7492478A2+54818]
	(No symbol) [0x00007FF7491B6AD2]
	(No symbol) [0x00007FF74906DA3B]
	(No symbol) [0x00007FF74907246D]
	(No symbol) [0x00007FF749073F5F]
	(No symbol) [0x00007FF749074050]
	(No symbol) [0x00007FF7490AE184]
	(No symbol) [0x00007FF7490AE67C]
	(No symbol) [0x00007FF7490A544C]
	(No symbol) [0x00007FF7490CEAEF]
	(No symbol) [0x00007FF7490A5036]
	(No symbol) [0x00007FF7490CECC0]
	(No symbol) [0x00007FF7490E75A2]
	(No symbol) [0x00007FF7490CE883]
	(No symbol) [0x00007FF7490A3691]
	(No symbol) [0x00007FF7490A48D4]
	GetHandleVerifier [0x00007FF7495AB9A2+3610402]
	GetHandleVerifier [0x00007FF749601870+3962352]
	GetHandleVerifier [0x00007FF7495F9D5F+3930847]
	GetHandleVerifier [0x00007FF7492E3656+693206]
	(No symbol) [0x00007FF7491C1638]
	(No symbol) [0x00007FF7491BD944]
	(No symbol) [0x00007FF7491BDA72]
	(No symbol) [0x00007FF7491AE123]
	BaseThreadInitThunk [0x00007FF9E8827344+20]
	RtlUserThreadStart [0x00007FF9E91DCC91+33]

2024-06-25 16:16:10 PM | DEBUG | Exception in start_automation: Message: stale element reference: stale element not found
  (Session info: chrome=117.0.5938.92); For documentation on this error, please visit: https://www.selenium.dev/documentation/webdriver/troubleshooting/errors#stale-element-reference-exception
Stacktrace:
	GetHandleVerifier [0x00007FF7492478A2+54818]
	(No symbol) [0x00007FF7491B6AD2]
	(No symbol) [0x00007FF74906DA3B]
	(No symbol) [0x00007FF74907246D]
	(No symbol) [0x00007FF749073F5F]
	(No symbol) [0x00007FF749074050]
	(No symbol) [0x00007FF7490AE184]
	(No symbol) [0x00007FF7490AE67C]
	(No symbol) [0x00007FF7490A544C]
	(No symbol) [0x00007FF7490CEAEF]
	(No symbol) [0x00007FF7490A5036]
	(No symbol) [0x00007FF7490CECC0]
	(No symbol) [0x00007FF7490E75A2]
	(No symbol) [0x00007FF7490CE883]
	(No symbol) [0x00007FF7490A3691]
	(No symbol) [0x00007FF7490A48D4]
	GetHandleVerifier [0x00007FF7495AB9A2+3610402]
	GetHandleVerifier [0x00007FF749601870+3962352]
	GetHandleVerifier [0x00007FF7495F9D5F+3930847]
	GetHandleVerifier [0x00007FF7492E3656+693206]
	(No symbol) [0x00007FF7491C1638]
	(No symbol) [0x00007FF7491BD944]
	(No symbol) [0x00007FF7491BDA72]
	(No symbol) [0x00007FF7491AE123]
	BaseThreadInitThunk [0x00007FF9E8827344+20]
	RtlUserThreadStart [0x00007FF9E91DCC91+33]

2024-06-25 16:16:10 PM | DEBUG | Exception in start_automation: Message: stale element reference: stale element not found
  (Session info: chrome=117.0.5938.92); For documentation on this error, please visit: https://www.selenium.dev/documentation/webdriver/troubleshooting/errors#stale-element-reference-exception
Stacktrace:
	GetHandleVerifier [0x00007FF7492478A2+54818]
	(No symbol) [0x00007FF7491B6AD2]
	(No symbol) [0x00007FF74906DA3B]
	(No symbol) [0x00007FF74907246D]
	(No symbol) [0x00007FF749073F5F]
	(No symbol) [0x00007FF749074050]
	(No symbol) [0x00007FF7490AE184]
	(No symbol) [0x00007FF7490AE67C]
	(No symbol) [0x00007FF7490A544C]
	(No symbol) [0x00007FF7490CEAEF]
	(No symbol) [0x00007FF7490A5036]
	(No symbol) [0x00007FF7490CECC0]
	(No symbol) [0x00007FF7490E75A2]
	(No symbol) [0x00007FF7490CE883]
	(No symbol) [0x00007FF7490A3691]
	(No symbol) [0x00007FF7490A48D4]
	GetHandleVerifier [0x00007FF7495AB9A2+3610402]
	GetHandleVerifier [0x00007FF749601870+3962352]
	GetHandleVerifier [0x00007FF7495F9D5F+3930847]
	GetHandleVerifier [0x00007FF7492E3656+693206]
	(No symbol) [0x00007FF7491C1638]
	(No symbol) [0x00007FF7491BD944]
	(No symbol) [0x00007FF7491BDA72]
	(No symbol) [0x00007FF7491AE123]
	BaseThreadInitThunk [0x00007FF9E8827344+20]
	RtlUserThreadStart [0x00007FF9E91DCC91+33]

2024-06-25 16:16:24 PM | DEBUG | Exception in delete_session: .sessions/default - The system cannot find the path specified
2024-06-25 16:19:53 PM | DEBUG | Exception in start_automation: Message: stale element reference: stale element not found
  (Session info: chrome=117.0.5938.92); For documentation on this error, please visit: https://www.selenium.dev/documentation/webdriver/troubleshooting/errors#stale-element-reference-exception
Stacktrace:
	GetHandleVerifier [0x00007FF7492478A2+54818]
	(No symbol) [0x00007FF7491B6AD2]
	(No symbol) [0x00007FF74906DA3B]
	(No symbol) [0x00007FF74907246D]
	(No symbol) [0x00007FF749073F5F]
	(No symbol) [0x00007FF749074050]
	(No symbol) [0x00007FF7490AE184]
	(No symbol) [0x00007FF7490AE67C]
	(No symbol) [0x00007FF7490A544C]
	(No symbol) [0x00007FF7490CEAEF]
	(No symbol) [0x00007FF7490A5036]
	(No symbol) [0x00007FF7490CECC0]
	(No symbol) [0x00007FF7490E75A2]
	(No symbol) [0x00007FF7490CE883]
	(No symbol) [0x00007FF7490A3691]
	(No symbol) [0x00007FF7490A48D4]
	GetHandleVerifier [0x00007FF7495AB9A2+3610402]
	GetHandleVerifier [0x00007FF749601870+3962352]
	GetHandleVerifier [0x00007FF7495F9D5F+3930847]
	GetHandleVerifier [0x00007FF7492E3656+693206]
	(No symbol) [0x00007FF7491C1638]
	(No symbol) [0x00007FF7491BD944]
	(No symbol) [0x00007FF7491BDA72]
	(No symbol) [0x00007FF7491AE123]
	BaseThreadInitThunk [0x00007FF9E8827344+20]
	RtlUserThreadStart [0x00007FF9E91DCC91+33]

2024-06-26 16:00:15 PM | DEBUG | Exception in start_automation: Message: stale element reference: stale element not found
  (Session info: chrome=117.0.5938.92); For documentation on this error, please visit: https://www.selenium.dev/documentation/webdriver/troubleshooting/errors#stale-element-reference-exception
Stacktrace:
	GetHandleVerifier [0x00007FF7736278A2+54818]
	(No symbol) [0x00007FF773596AD2]
	(No symbol) [0x00007FF77344DA3B]
	(No symbol) [0x00007FF77345246D]
	(No symbol) [0x00007FF773453F5F]
	(No symbol) [0x00007FF773454050]
	(No symbol) [0x00007FF77348E184]
	(No symbol) [0x00007FF77348E67C]
	(No symbol) [0x00007FF77348544C]
	(No symbol) [0x00007FF7734AEAEF]
	(No symbol) [0x00007FF773485036]
	(No symbol) [0x00007FF7734AECC0]
	(No symbol) [0x00007FF7734C75A2]
	(No symbol) [0x00007FF7734AE883]
	(No symbol) [0x00007FF773483691]
	(No symbol) [0x00007FF7734848D4]
	GetHandleVerifier [0x00007FF77398B9A2+3610402]
	GetHandleVerifier [0x00007FF7739E1870+3962352]
	GetHandleVerifier [0x00007FF7739D9D5F+3930847]
	GetHandleVerifier [0x00007FF7736C3656+693206]
	(No symbol) [0x00007FF7735A1638]
	(No symbol) [0x00007FF77359D944]
	(No symbol) [0x00007FF77359DA72]
	(No symbol) [0x00007FF77358E123]
	BaseThreadInitThunk [0x00007FFEF42E7344+20]
	RtlUserThreadStart [0x00007FFEF4A3CC91+33]

2024-06-26 16:00:15 PM | DEBUG | Exception in start_automation: Message: stale element reference: stale element not found
  (Session info: chrome=117.0.5938.92); For documentation on this error, please visit: https://www.selenium.dev/documentation/webdriver/troubleshooting/errors#stale-element-reference-exception
Stacktrace:
	GetHandleVerifier [0x00007FF7736278A2+54818]
	(No symbol) [0x00007FF773596AD2]
	(No symbol) [0x00007FF77344DA3B]
	(No symbol) [0x00007FF77345246D]
	(No symbol) [0x00007FF773453F5F]
	(No symbol) [0x00007FF773454050]
	(No symbol) [0x00007FF77348E184]
	(No symbol) [0x00007FF77348E67C]
	(No symbol) [0x00007FF77348544C]
	(No symbol) [0x00007FF7734AEAEF]
	(No symbol) [0x00007FF773485036]
	(No symbol) [0x00007FF7734AECC0]
	(No symbol) [0x00007FF7734C75A2]
	(No symbol) [0x00007FF7734AE883]
	(No symbol) [0x00007FF773483691]
	(No symbol) [0x00007FF7734848D4]
	GetHandleVerifier [0x00007FF77398B9A2+3610402]
	GetHandleVerifier [0x00007FF7739E1870+3962352]
	GetHandleVerifier [0x00007FF7739D9D5F+3930847]
	GetHandleVerifier [0x00007FF7736C3656+693206]
	(No symbol) [0x00007FF7735A1638]
	(No symbol) [0x00007FF77359D944]
	(No symbol) [0x00007FF77359DA72]
	(No symbol) [0x00007FF77358E123]
	BaseThreadInitThunk [0x00007FFEF42E7344+20]
	RtlUserThreadStart [0x00007FFEF4A3CC91+33]

2024-06-26 16:00:15 PM | DEBUG | Exception in start_automation: Message: stale element reference: stale element not found
  (Session info: chrome=117.0.5938.92); For documentation on this error, please visit: https://www.selenium.dev/documentation/webdriver/troubleshooting/errors#stale-element-reference-exception
Stacktrace:
	GetHandleVerifier [0x00007FF7736278A2+54818]
	(No symbol) [0x00007FF773596AD2]
	(No symbol) [0x00007FF77344DA3B]
	(No symbol) [0x00007FF77345246D]
	(No symbol) [0x00007FF773453F5F]
	(No symbol) [0x00007FF773454050]
	(No symbol) [0x00007FF77348E184]
	(No symbol) [0x00007FF77348E67C]
	(No symbol) [0x00007FF77348544C]
	(No symbol) [0x00007FF7734AEAEF]
	(No symbol) [0x00007FF773485036]
	(No symbol) [0x00007FF7734AECC0]
	(No symbol) [0x00007FF7734C75A2]
	(No symbol) [0x00007FF7734AE883]
	(No symbol) [0x00007FF773483691]
	(No symbol) [0x00007FF7734848D4]
	GetHandleVerifier [0x00007FF77398B9A2+3610402]
	GetHandleVerifier [0x00007FF7739E1870+3962352]
	GetHandleVerifier [0x00007FF7739D9D5F+3930847]
	GetHandleVerifier [0x00007FF7736C3656+693206]
	(No symbol) [0x00007FF7735A1638]
	(No symbol) [0x00007FF77359D944]
	(No symbol) [0x00007FF77359DA72]
	(No symbol) [0x00007FF77358E123]
	BaseThreadInitThunk [0x00007FFEF42E7344+20]
	RtlUserThreadStart [0x00007FFEF4A3CC91+33]

2024-06-26 16:00:58 PM | ERROR | Exception in start_session: Element not found
2024-06-26 16:28:58 PM | DEBUG | Exception in start_automation: Message: stale element reference: stale element not found
  (Session info: chrome=117.0.5938.92); For documentation on this error, please visit: https://www.selenium.dev/documentation/webdriver/troubleshooting/errors#stale-element-reference-exception
Stacktrace:
	GetHandleVerifier [0x00007FF7736278A2+54818]
	(No symbol) [0x00007FF773596AD2]
	(No symbol) [0x00007FF77344DA3B]
	(No symbol) [0x00007FF77345246D]
	(No symbol) [0x00007FF773453F5F]
	(No symbol) [0x00007FF773454050]
	(No symbol) [0x00007FF77348E184]
	(No symbol) [0x00007FF77348E67C]
	(No symbol) [0x00007FF77348544C]
	(No symbol) [0x00007FF7734AEAEF]
	(No symbol) [0x00007FF773485036]
	(No symbol) [0x00007FF7734AECC0]
	(No symbol) [0x00007FF7734C75A2]
	(No symbol) [0x00007FF7734AE883]
	(No symbol) [0x00007FF773483691]
	(No symbol) [0x00007FF7734848D4]
	GetHandleVerifier [0x00007FF77398B9A2+3610402]
	GetHandleVerifier [0x00007FF7739E1870+3962352]
	GetHandleVerifier [0x00007FF7739D9D5F+3930847]
	GetHandleVerifier [0x00007FF7736C3656+693206]
	(No symbol) [0x00007FF7735A1638]
	(No symbol) [0x00007FF77359D944]
	(No symbol) [0x00007FF77359DA72]
	(No symbol) [0x00007FF77358E123]
	BaseThreadInitThunk [0x00007FFEF42E7344+20]
	RtlUserThreadStart [0x00007FFEF4A3CC91+33]

2024-06-26 16:28:58 PM | DEBUG | Exception in start_automation: Message: stale element reference: stale element not found
  (Session info: chrome=117.0.5938.92); For documentation on this error, please visit: https://www.selenium.dev/documentation/webdriver/troubleshooting/errors#stale-element-reference-exception
Stacktrace:
	GetHandleVerifier [0x00007FF7736278A2+54818]
	(No symbol) [0x00007FF773596AD2]
	(No symbol) [0x00007FF77344DA3B]
	(No symbol) [0x00007FF77345246D]
	(No symbol) [0x00007FF773453F5F]
	(No symbol) [0x00007FF773454050]
	(No symbol) [0x00007FF77348E184]
	(No symbol) [0x00007FF77348E67C]
	(No symbol) [0x00007FF77348544C]
	(No symbol) [0x00007FF7734AEAEF]
	(No symbol) [0x00007FF773485036]
	(No symbol) [0x00007FF7734AECC0]
	(No symbol) [0x00007FF7734C75A2]
	(No symbol) [0x00007FF7734AE883]
	(No symbol) [0x00007FF773483691]
	(No symbol) [0x00007FF7734848D4]
	GetHandleVerifier [0x00007FF77398B9A2+3610402]
	GetHandleVerifier [0x00007FF7739E1870+3962352]
	GetHandleVerifier [0x00007FF7739D9D5F+3930847]
	GetHandleVerifier [0x00007FF7736C3656+693206]
	(No symbol) [0x00007FF7735A1638]
	(No symbol) [0x00007FF77359D944]
	(No symbol) [0x00007FF77359DA72]
	(No symbol) [0x00007FF77358E123]
	BaseThreadInitThunk [0x00007FFEF42E7344+20]
	RtlUserThreadStart [0x00007FFEF4A3CC91+33]

2024-06-26 16:28:58 PM | DEBUG | Exception in start_automation: Message: stale element reference: stale element not found
  (Session info: chrome=117.0.5938.92); For documentation on this error, please visit: https://www.selenium.dev/documentation/webdriver/troubleshooting/errors#stale-element-reference-exception
Stacktrace:
	GetHandleVerifier [0x00007FF7736278A2+54818]
	(No symbol) [0x00007FF773596AD2]
	(No symbol) [0x00007FF77344DA3B]
	(No symbol) [0x00007FF77345246D]
	(No symbol) [0x00007FF773453F5F]
	(No symbol) [0x00007FF773454050]
	(No symbol) [0x00007FF77348E184]
	(No symbol) [0x00007FF77348E67C]
	(No symbol) [0x00007FF77348544C]
	(No symbol) [0x00007FF7734AEAEF]
	(No symbol) [0x00007FF773485036]
	(No symbol) [0x00007FF7734AECC0]
	(No symbol) [0x00007FF7734C75A2]
	(No symbol) [0x00007FF7734AE883]
	(No symbol) [0x00007FF773483691]
	(No symbol) [0x00007FF7734848D4]
	GetHandleVerifier [0x00007FF77398B9A2+3610402]
	GetHandleVerifier [0x00007FF7739E1870+3962352]
	GetHandleVerifier [0x00007FF7739D9D5F+3930847]
	GetHandleVerifier [0x00007FF7736C3656+693206]
	(No symbol) [0x00007FF7735A1638]
	(No symbol) [0x00007FF77359D944]
	(No symbol) [0x00007FF77359DA72]
	(No symbol) [0x00007FF77358E123]
	BaseThreadInitThunk [0x00007FFEF42E7344+20]
	RtlUserThreadStart [0x00007FFEF4A3CC91+33]

2024-06-26 16:41:07 PM | DEBUG | Exception in start_automation: Message: stale element reference: stale element not found
  (Session info: chrome=117.0.5938.92); For documentation on this error, please visit: https://www.selenium.dev/documentation/webdriver/troubleshooting/errors#stale-element-reference-exception
Stacktrace:
	GetHandleVerifier [0x00007FF7736278A2+54818]
	(No symbol) [0x00007FF773596AD2]
	(No symbol) [0x00007FF77344DA3B]
	(No symbol) [0x00007FF77345246D]
	(No symbol) [0x00007FF773453F5F]
	(No symbol) [0x00007FF773454050]
	(No symbol) [0x00007FF77348E184]
	(No symbol) [0x00007FF77348E67C]
	(No symbol) [0x00007FF77348544C]
	(No symbol) [0x00007FF7734AEAEF]
	(No symbol) [0x00007FF773485036]
	(No symbol) [0x00007FF7734AECC0]
	(No symbol) [0x00007FF7734C75A2]
	(No symbol) [0x00007FF7734AE883]
	(No symbol) [0x00007FF773483691]
	(No symbol) [0x00007FF7734848D4]
	GetHandleVerifier [0x00007FF77398B9A2+3610402]
	GetHandleVerifier [0x00007FF7739E1870+3962352]
	GetHandleVerifier [0x00007FF7739D9D5F+3930847]
	GetHandleVerifier [0x00007FF7736C3656+693206]
	(No symbol) [0x00007FF7735A1638]
	(No symbol) [0x00007FF77359D944]
	(No symbol) [0x00007FF77359DA72]
	(No symbol) [0x00007FF77358E123]
	BaseThreadInitThunk [0x00007FFEF42E7344+20]
	RtlUserThreadStart [0x00007FFEF4A3CC91+33]

2024-06-26 16:41:07 PM | DEBUG | Exception in start_automation: Message: stale element reference: stale element not found
  (Session info: chrome=117.0.5938.92); For documentation on this error, please visit: https://www.selenium.dev/documentation/webdriver/troubleshooting/errors#stale-element-reference-exception
Stacktrace:
	GetHandleVerifier [0x00007FF7736278A2+54818]
	(No symbol) [0x00007FF773596AD2]
	(No symbol) [0x00007FF77344DA3B]
	(No symbol) [0x00007FF77345246D]
	(No symbol) [0x00007FF773453F5F]
	(No symbol) [0x00007FF773454050]
	(No symbol) [0x00007FF77348E184]
	(No symbol) [0x00007FF77348E67C]
	(No symbol) [0x00007FF77348544C]
	(No symbol) [0x00007FF7734AEAEF]
	(No symbol) [0x00007FF773485036]
	(No symbol) [0x00007FF7734AECC0]
	(No symbol) [0x00007FF7734C75A2]
	(No symbol) [0x00007FF7734AE883]
	(No symbol) [0x00007FF773483691]
	(No symbol) [0x00007FF7734848D4]
	GetHandleVerifier [0x00007FF77398B9A2+3610402]
	GetHandleVerifier [0x00007FF7739E1870+3962352]
	GetHandleVerifier [0x00007FF7739D9D5F+3930847]
	GetHandleVerifier [0x00007FF7736C3656+693206]
	(No symbol) [0x00007FF7735A1638]
	(No symbol) [0x00007FF77359D944]
	(No symbol) [0x00007FF77359DA72]
	(No symbol) [0x00007FF77358E123]
	BaseThreadInitThunk [0x00007FFEF42E7344+20]
	RtlUserThreadStart [0x00007FFEF4A3CC91+33]

2024-06-26 16:42:32 PM | DEBUG | Exception in start_automation: Message: stale element reference: stale element not found
  (Session info: chrome=117.0.5938.92); For documentation on this error, please visit: https://www.selenium.dev/documentation/webdriver/troubleshooting/errors#stale-element-reference-exception
Stacktrace:
	GetHandleVerifier [0x00007FF7736278A2+54818]
	(No symbol) [0x00007FF773596AD2]
	(No symbol) [0x00007FF77344DA3B]
	(No symbol) [0x00007FF77345246D]
	(No symbol) [0x00007FF773453F5F]
	(No symbol) [0x00007FF773454050]
	(No symbol) [0x00007FF77348E184]
	(No symbol) [0x00007FF77348E67C]
	(No symbol) [0x00007FF77348544C]
	(No symbol) [0x00007FF7734AEAEF]
	(No symbol) [0x00007FF773485036]
	(No symbol) [0x00007FF7734AECC0]
	(No symbol) [0x00007FF7734C75A2]
	(No symbol) [0x00007FF7734AE883]
	(No symbol) [0x00007FF773483691]
	(No symbol) [0x00007FF7734848D4]
	GetHandleVerifier [0x00007FF77398B9A2+3610402]
	GetHandleVerifier [0x00007FF7739E1870+3962352]
	GetHandleVerifier [0x00007FF7739D9D5F+3930847]
	GetHandleVerifier [0x00007FF7736C3656+693206]
	(No symbol) [0x00007FF7735A1638]
	(No symbol) [0x00007FF77359D944]
	(No symbol) [0x00007FF77359DA72]
	(No symbol) [0x00007FF77358E123]
	BaseThreadInitThunk [0x00007FFEF42E7344+20]
	RtlUserThreadStart [0x00007FFEF4A3CC91+33]

2024-06-26 16:42:33 PM | DEBUG | Exception in start_automation: Message: stale element reference: stale element not found
  (Session info: chrome=117.0.5938.92); For documentation on this error, please visit: https://www.selenium.dev/documentation/webdriver/troubleshooting/errors#stale-element-reference-exception
Stacktrace:
	GetHandleVerifier [0x00007FF7736278A2+54818]
	(No symbol) [0x00007FF773596AD2]
	(No symbol) [0x00007FF77344DA3B]
	(No symbol) [0x00007FF77345246D]
	(No symbol) [0x00007FF773453F5F]
	(No symbol) [0x00007FF773454050]
	(No symbol) [0x00007FF77348E184]
	(No symbol) [0x00007FF77348E67C]
	(No symbol) [0x00007FF77348544C]
	(No symbol) [0x00007FF7734AEAEF]
	(No symbol) [0x00007FF773485036]
	(No symbol) [0x00007FF7734AECC0]
	(No symbol) [0x00007FF7734C75A2]
	(No symbol) [0x00007FF7734AE883]
	(No symbol) [0x00007FF773483691]
	(No symbol) [0x00007FF7734848D4]
	GetHandleVerifier [0x00007FF77398B9A2+3610402]
	GetHandleVerifier [0x00007FF7739E1870+3962352]
	GetHandleVerifier [0x00007FF7739D9D5F+3930847]
	GetHandleVerifier [0x00007FF7736C3656+693206]
	(No symbol) [0x00007FF7735A1638]
	(No symbol) [0x00007FF77359D944]
	(No symbol) [0x00007FF77359DA72]
	(No symbol) [0x00007FF77358E123]
	BaseThreadInitThunk [0x00007FFEF42E7344+20]
	RtlUserThreadStart [0x00007FFEF4A3CC91+33]

2024-06-26 16:42:33 PM | DEBUG | Exception in start_automation: Message: stale element reference: stale element not found
  (Session info: chrome=117.0.5938.92); For documentation on this error, please visit: https://www.selenium.dev/documentation/webdriver/troubleshooting/errors#stale-element-reference-exception
Stacktrace:
	GetHandleVerifier [0x00007FF7736278A2+54818]
	(No symbol) [0x00007FF773596AD2]
	(No symbol) [0x00007FF77344DA3B]
	(No symbol) [0x00007FF77345246D]
	(No symbol) [0x00007FF773453F5F]
	(No symbol) [0x00007FF773454050]
	(No symbol) [0x00007FF77348E184]
	(No symbol) [0x00007FF77348E67C]
	(No symbol) [0x00007FF77348544C]
	(No symbol) [0x00007FF7734AEAEF]
	(No symbol) [0x00007FF773485036]
	(No symbol) [0x00007FF7734AECC0]
	(No symbol) [0x00007FF7734C75A2]
	(No symbol) [0x00007FF7734AE883]
	(No symbol) [0x00007FF773483691]
	(No symbol) [0x00007FF7734848D4]
	GetHandleVerifier [0x00007FF77398B9A2+3610402]
	GetHandleVerifier [0x00007FF7739E1870+3962352]
	GetHandleVerifier [0x00007FF7739D9D5F+3930847]
	GetHandleVerifier [0x00007FF7736C3656+693206]
	(No symbol) [0x00007FF7735A1638]
	(No symbol) [0x00007FF77359D944]
	(No symbol) [0x00007FF77359DA72]
	(No symbol) [0x00007FF77358E123]
	BaseThreadInitThunk [0x00007FFEF42E7344+20]
	RtlUserThreadStart [0x00007FFEF4A3CC91+33]

2024-06-27 14:49:19 PM | DEBUG | Exception in start_automation: Message: stale element reference: stale element not found
  (Session info: chrome=117.0.5938.92); For documentation on this error, please visit: https://www.selenium.dev/documentation/webdriver/troubleshooting/errors#stale-element-reference-exception
Stacktrace:
	GetHandleVerifier [0x00007FF7963C78A2+54818]
	(No symbol) [0x00007FF796336AD2]
	(No symbol) [0x00007FF7961EDA3B]
	(No symbol) [0x00007FF7961F246D]
	(No symbol) [0x00007FF7961F3F5F]
	(No symbol) [0x00007FF7961F4050]
	(No symbol) [0x00007FF79622E184]
	(No symbol) [0x00007FF79622E67C]
	(No symbol) [0x00007FF79622544C]
	(No symbol) [0x00007FF79624EAEF]
	(No symbol) [0x00007FF796225036]
	(No symbol) [0x00007FF79624ECC0]
	(No symbol) [0x00007FF7962675A2]
	(No symbol) [0x00007FF79624E883]
	(No symbol) [0x00007FF796223691]
	(No symbol) [0x00007FF7962248D4]
	GetHandleVerifier [0x00007FF79672B9A2+3610402]
	GetHandleVerifier [0x00007FF796781870+3962352]
	GetHandleVerifier [0x00007FF796779D5F+3930847]
	GetHandleVerifier [0x00007FF796463656+693206]
	(No symbol) [0x00007FF796341638]
	(No symbol) [0x00007FF79633D944]
	(No symbol) [0x00007FF79633DA72]
	(No symbol) [0x00007FF79632E123]
	BaseThreadInitThunk [0x00007FFEF42E7344+20]
	RtlUserThreadStart [0x00007FFEF4A3CC91+33]

2024-06-27 14:49:19 PM | DEBUG | Exception in start_automation: Message: stale element reference: stale element not found
  (Session info: chrome=117.0.5938.92); For documentation on this error, please visit: https://www.selenium.dev/documentation/webdriver/troubleshooting/errors#stale-element-reference-exception
Stacktrace:
	GetHandleVerifier [0x00007FF7963C78A2+54818]
	(No symbol) [0x00007FF796336AD2]
	(No symbol) [0x00007FF7961EDA3B]
	(No symbol) [0x00007FF7961F246D]
	(No symbol) [0x00007FF7961F3F5F]
	(No symbol) [0x00007FF7961F4050]
	(No symbol) [0x00007FF79622E184]
	(No symbol) [0x00007FF79622E67C]
	(No symbol) [0x00007FF79622544C]
	(No symbol) [0x00007FF79624EAEF]
	(No symbol) [0x00007FF796225036]
	(No symbol) [0x00007FF79624ECC0]
	(No symbol) [0x00007FF7962675A2]
	(No symbol) [0x00007FF79624E883]
	(No symbol) [0x00007FF796223691]
	(No symbol) [0x00007FF7962248D4]
	GetHandleVerifier [0x00007FF79672B9A2+3610402]
	GetHandleVerifier [0x00007FF796781870+3962352]
	GetHandleVerifier [0x00007FF796779D5F+3930847]
	GetHandleVerifier [0x00007FF796463656+693206]
	(No symbol) [0x00007FF796341638]
	(No symbol) [0x00007FF79633D944]
	(No symbol) [0x00007FF79633DA72]
	(No symbol) [0x00007FF79632E123]
	BaseThreadInitThunk [0x00007FFEF42E7344+20]
	RtlUserThreadStart [0x00007FFEF4A3CC91+33]

2024-06-27 14:49:19 PM | DEBUG | Exception in start_automation: Message: stale element reference: stale element not found
  (Session info: chrome=117.0.5938.92); For documentation on this error, please visit: https://www.selenium.dev/documentation/webdriver/troubleshooting/errors#stale-element-reference-exception
Stacktrace:
	GetHandleVerifier [0x00007FF7963C78A2+54818]
	(No symbol) [0x00007FF796336AD2]
	(No symbol) [0x00007FF7961EDA3B]
	(No symbol) [0x00007FF7961F246D]
	(No symbol) [0x00007FF7961F3F5F]
	(No symbol) [0x00007FF7961F4050]
	(No symbol) [0x00007FF79622E184]
	(No symbol) [0x00007FF79622E67C]
	(No symbol) [0x00007FF79622544C]
	(No symbol) [0x00007FF79624EAEF]
	(No symbol) [0x00007FF796225036]
	(No symbol) [0x00007FF79624ECC0]
	(No symbol) [0x00007FF7962675A2]
	(No symbol) [0x00007FF79624E883]
	(No symbol) [0x00007FF796223691]
	(No symbol) [0x00007FF7962248D4]
	GetHandleVerifier [0x00007FF79672B9A2+3610402]
	GetHandleVerifier [0x00007FF796781870+3962352]
	GetHandleVerifier [0x00007FF796779D5F+3930847]
	GetHandleVerifier [0x00007FF796463656+693206]
	(No symbol) [0x00007FF796341638]
	(No symbol) [0x00007FF79633D944]
	(No symbol) [0x00007FF79633DA72]
	(No symbol) [0x00007FF79632E123]
	BaseThreadInitThunk [0x00007FFEF42E7344+20]
	RtlUserThreadStart [0x00007FFEF4A3CC91+33]

2024-06-27 14:52:46 PM | DEBUG | Exception in delete_session: .sessions/default - The system cannot find the path specified
2024-06-28 11:26:27 AM | ERROR | Exception in restore_a_session: Message: Unable to locate or obtain driver for chrome; For documentation on this error, please visit: https://www.selenium.dev/documentation/webdriver/troubleshooting/errors/driver_location

2024-06-28 12:45:52 PM | DEBUG | Exception in start_automation: Message: stale element reference: stale element not found
  (Session info: chrome=117.0.5938.92); For documentation on this error, please visit: https://www.selenium.dev/documentation/webdriver/troubleshooting/errors#stale-element-reference-exception
Stacktrace:
	GetHandleVerifier [0x00007FF6341C78A2+54818]
	(No symbol) [0x00007FF634136AD2]
	(No symbol) [0x00007FF633FEDA3B]
	(No symbol) [0x00007FF633FF246D]
	(No symbol) [0x00007FF633FF3F5F]
	(No symbol) [0x00007FF633FF4050]
	(No symbol) [0x00007FF63402E184]
	(No symbol) [0x00007FF63402E67C]
	(No symbol) [0x00007FF63402544C]
	(No symbol) [0x00007FF63404EAEF]
	(No symbol) [0x00007FF634025036]
	(No symbol) [0x00007FF63404ECC0]
	(No symbol) [0x00007FF6340675A2]
	(No symbol) [0x00007FF63404E883]
	(No symbol) [0x00007FF634023691]
	(No symbol) [0x00007FF6340248D4]
	GetHandleVerifier [0x00007FF63452B9A2+3610402]
	GetHandleVerifier [0x00007FF634581870+3962352]
	GetHandleVerifier [0x00007FF634579D5F+3930847]
	GetHandleVerifier [0x00007FF634263656+693206]
	(No symbol) [0x00007FF634141638]
	(No symbol) [0x00007FF63413D944]
	(No symbol) [0x00007FF63413DA72]
	(No symbol) [0x00007FF63412E123]
	BaseThreadInitThunk [0x00007FFEF42E7344+20]
	RtlUserThreadStart [0x00007FFEF4A3CC91+33]

2024-06-28 12:45:52 PM | DEBUG | Exception in start_automation: Message: stale element reference: stale element not found
  (Session info: chrome=117.0.5938.92); For documentation on this error, please visit: https://www.selenium.dev/documentation/webdriver/troubleshooting/errors#stale-element-reference-exception
Stacktrace:
	GetHandleVerifier [0x00007FF6341C78A2+54818]
	(No symbol) [0x00007FF634136AD2]
	(No symbol) [0x00007FF633FEDA3B]
	(No symbol) [0x00007FF633FF246D]
	(No symbol) [0x00007FF633FF3F5F]
	(No symbol) [0x00007FF633FF4050]
	(No symbol) [0x00007FF63402E184]
	(No symbol) [0x00007FF63402E67C]
	(No symbol) [0x00007FF63402544C]
	(No symbol) [0x00007FF63404EAEF]
	(No symbol) [0x00007FF634025036]
	(No symbol) [0x00007FF63404ECC0]
	(No symbol) [0x00007FF6340675A2]
	(No symbol) [0x00007FF63404E883]
	(No symbol) [0x00007FF634023691]
	(No symbol) [0x00007FF6340248D4]
	GetHandleVerifier [0x00007FF63452B9A2+3610402]
	GetHandleVerifier [0x00007FF634581870+3962352]
	GetHandleVerifier [0x00007FF634579D5F+3930847]
	GetHandleVerifier [0x00007FF634263656+693206]
	(No symbol) [0x00007FF634141638]
	(No symbol) [0x00007FF63413D944]
	(No symbol) [0x00007FF63413DA72]
	(No symbol) [0x00007FF63412E123]
	BaseThreadInitThunk [0x00007FFEF42E7344+20]
	RtlUserThreadStart [0x00007FFEF4A3CC91+33]

2024-06-28 12:53:54 PM | DEBUG | Exception in start_automation: Message: stale element reference: stale element not found
  (Session info: chrome=117.0.5938.92); For documentation on this error, please visit: https://www.selenium.dev/documentation/webdriver/troubleshooting/errors#stale-element-reference-exception
Stacktrace:
	GetHandleVerifier [0x00007FF6341C78A2+54818]
	(No symbol) [0x00007FF634136AD2]
	(No symbol) [0x00007FF633FEDA3B]
	(No symbol) [0x00007FF633FF246D]
	(No symbol) [0x00007FF633FF3F5F]
	(No symbol) [0x00007FF633FF4050]
	(No symbol) [0x00007FF63402E184]
	(No symbol) [0x00007FF63402E67C]
	(No symbol) [0x00007FF63402544C]
	(No symbol) [0x00007FF63404EAEF]
	(No symbol) [0x00007FF634025036]
	(No symbol) [0x00007FF63404ECC0]
	(No symbol) [0x00007FF6340675A2]
	(No symbol) [0x00007FF63404E883]
	(No symbol) [0x00007FF634023691]
	(No symbol) [0x00007FF6340248D4]
	GetHandleVerifier [0x00007FF63452B9A2+3610402]
	GetHandleVerifier [0x00007FF634581870+3962352]
	GetHandleVerifier [0x00007FF634579D5F+3930847]
	GetHandleVerifier [0x00007FF634263656+693206]
	(No symbol) [0x00007FF634141638]
	(No symbol) [0x00007FF63413D944]
	(No symbol) [0x00007FF63413DA72]
	(No symbol) [0x00007FF63412E123]
	BaseThreadInitThunk [0x00007FFEF42E7344+20]
	RtlUserThreadStart [0x00007FFEF4A3CC91+33]

2024-06-28 12:53:54 PM | DEBUG | Exception in start_automation: Message: stale element reference: stale element not found
  (Session info: chrome=117.0.5938.92); For documentation on this error, please visit: https://www.selenium.dev/documentation/webdriver/troubleshooting/errors#stale-element-reference-exception
Stacktrace:
	GetHandleVerifier [0x00007FF6341C78A2+54818]
	(No symbol) [0x00007FF634136AD2]
	(No symbol) [0x00007FF633FEDA3B]
	(No symbol) [0x00007FF633FF246D]
	(No symbol) [0x00007FF633FF3F5F]
	(No symbol) [0x00007FF633FF4050]
	(No symbol) [0x00007FF63402E184]
	(No symbol) [0x00007FF63402E67C]
	(No symbol) [0x00007FF63402544C]
	(No symbol) [0x00007FF63404EAEF]
	(No symbol) [0x00007FF634025036]
	(No symbol) [0x00007FF63404ECC0]
	(No symbol) [0x00007FF6340675A2]
	(No symbol) [0x00007FF63404E883]
	(No symbol) [0x00007FF634023691]
	(No symbol) [0x00007FF6340248D4]
	GetHandleVerifier [0x00007FF63452B9A2+3610402]
	GetHandleVerifier [0x00007FF634581870+3962352]
	GetHandleVerifier [0x00007FF634579D5F+3930847]
	GetHandleVerifier [0x00007FF634263656+693206]
	(No symbol) [0x00007FF634141638]
	(No symbol) [0x00007FF63413D944]
	(No symbol) [0x00007FF63413DA72]
	(No symbol) [0x00007FF63412E123]
	BaseThreadInitThunk [0x00007FFEF42E7344+20]
	RtlUserThreadStart [0x00007FFEF4A3CC91+33]

2024-06-28 12:53:54 PM | DEBUG | Exception in start_automation: Message: stale element reference: stale element not found
  (Session info: chrome=117.0.5938.92); For documentation on this error, please visit: https://www.selenium.dev/documentation/webdriver/troubleshooting/errors#stale-element-reference-exception
Stacktrace:
	GetHandleVerifier [0x00007FF6341C78A2+54818]
	(No symbol) [0x00007FF634136AD2]
	(No symbol) [0x00007FF633FEDA3B]
	(No symbol) [0x00007FF633FF246D]
	(No symbol) [0x00007FF633FF3F5F]
	(No symbol) [0x00007FF633FF4050]
	(No symbol) [0x00007FF63402E184]
	(No symbol) [0x00007FF63402E67C]
	(No symbol) [0x00007FF63402544C]
	(No symbol) [0x00007FF63404EAEF]
	(No symbol) [0x00007FF634025036]
	(No symbol) [0x00007FF63404ECC0]
	(No symbol) [0x00007FF6340675A2]
	(No symbol) [0x00007FF63404E883]
	(No symbol) [0x00007FF634023691]
	(No symbol) [0x00007FF6340248D4]
	GetHandleVerifier [0x00007FF63452B9A2+3610402]
	GetHandleVerifier [0x00007FF634581870+3962352]
	GetHandleVerifier [0x00007FF634579D5F+3930847]
	GetHandleVerifier [0x00007FF634263656+693206]
	(No symbol) [0x00007FF634141638]
	(No symbol) [0x00007FF63413D944]
	(No symbol) [0x00007FF63413DA72]
	(No symbol) [0x00007FF63412E123]
	BaseThreadInitThunk [0x00007FFEF42E7344+20]
	RtlUserThreadStart [0x00007FFEF4A3CC91+33]

2024-10-09 10:22:12 AM | ERROR | Exception in track_message_recive: HTTPSConnectionPool(host='ihsancrm.com', port=443): Max retries exceeded with url: /api/ihsanai/faceAi/receive (Caused by NewConnectionError('<urllib3.connection.HTTPSConnection object at 0x000001D2E380D660>: Failed to establish a new connection: [Errno 11002] getaddrinfo failed'))
2024-10-09 10:22:15 AM | ERROR | Exception in ihsan_ai_bot: HTTPSConnectionPool(host='bot.ihsancrm.com', port=443): Max retries exceeded with url: /ihsanai/ask/query (Caused by NewConnectionError('<urllib3.connection.HTTPSConnection object at 0x000001D2E380C6A0>: Failed to establish a new connection: [Errno 11002] getaddrinfo failed'))
2024-10-09 10:22:18 AM | ERROR | Exception in track_message_recive: HTTPSConnectionPool(host='ihsancrm.com', port=443): Max retries exceeded with url: /api/ihsanai/faceAi/receive (Caused by NewConnectionError('<urllib3.connection.HTTPSConnection object at 0x000001D2E380D870>: Failed to establish a new connection: [Errno 11002] getaddrinfo failed'))
2024-10-09 10:22:19 AM | ERROR | Exception in ihsan_ai_bot: HTTPSConnectionPool(host='bot.ihsancrm.com', port=443): Max retries exceeded with url: /ihsanai/ask/query (Caused by NewConnectionError('<urllib3.connection.HTTPSConnection object at 0x000001D2E380C670>: Failed to establish a new connection: [Errno 11002] getaddrinfo failed'))
2024-10-09 10:22:21 AM | ERROR | Exception in track_message_recive: HTTPSConnectionPool(host='ihsancrm.com', port=443): Max retries exceeded with url: /api/ihsanai/faceAi/receive (Caused by NewConnectionError('<urllib3.connection.HTTPSConnection object at 0x000001D2E380D690>: Failed to establish a new connection: [Errno 11002] getaddrinfo failed'))
2024-10-09 10:22:21 AM | ERROR | Exception in ihsan_ai_bot: HTTPSConnectionPool(host='bot.ihsancrm.com', port=443): Max retries exceeded with url: /ihsanai/ask/query (Caused by NewConnectionError('<urllib3.connection.HTTPSConnection object at 0x000001D2E380CA60>: Failed to establish a new connection: [Errno 11002] getaddrinfo failed'))
2024-10-09 10:22:24 AM | ERROR | Exception in track_message_recive: HTTPSConnectionPool(host='ihsancrm.com', port=443): Max retries exceeded with url: /api/ihsanai/faceAi/receive (Caused by NewConnectionError('<urllib3.connection.HTTPSConnection object at 0x000001D2E380D4B0>: Failed to establish a new connection: [Errno 11002] getaddrinfo failed'))
2024-10-09 10:22:24 AM | ERROR | Exception in ihsan_ai_bot: HTTPSConnectionPool(host='bot.ihsancrm.com', port=443): Max retries exceeded with url: /ihsanai/ask/query (Caused by NewConnectionError('<urllib3.connection.HTTPSConnection object at 0x000001D2E380CDF0>: Failed to establish a new connection: [Errno 11002] getaddrinfo failed'))
2024-10-09 10:22:26 AM | ERROR | Exception in track_message_recive: HTTPSConnectionPool(host='ihsancrm.com', port=443): Max retries exceeded with url: /api/ihsanai/faceAi/receive (Caused by NewConnectionError('<urllib3.connection.HTTPSConnection object at 0x000001D2E380CEE0>: Failed to establish a new connection: [Errno 11002] getaddrinfo failed'))
2024-10-09 10:22:26 AM | ERROR | Exception in ihsan_ai_bot: HTTPSConnectionPool(host='bot.ihsancrm.com', port=443): Max retries exceeded with url: /ihsanai/ask/query (Caused by NewConnectionError('<urllib3.connection.HTTPSConnection object at 0x000001D2E380C6D0>: Failed to establish a new connection: [Errno 11002] getaddrinfo failed'))
2024-10-09 10:22:29 AM | ERROR | Exception in track_message_recive: HTTPSConnectionPool(host='ihsancrm.com', port=443): Max retries exceeded with url: /api/ihsanai/faceAi/receive (Caused by NewConnectionError('<urllib3.connection.HTTPSConnection object at 0x000001D2E380CEB0>: Failed to establish a new connection: [Errno 11002] getaddrinfo failed'))
2024-10-09 10:22:30 AM | ERROR | Exception in ihsan_ai_bot: HTTPSConnectionPool(host='bot.ihsancrm.com', port=443): Max retries exceeded with url: /ihsanai/ask/query (Caused by NewConnectionError('<urllib3.connection.HTTPSConnection object at 0x000001D2E380C970>: Failed to establish a new connection: [Errno 11002] getaddrinfo failed'))
2024-10-09 10:22:32 AM | ERROR | Exception in track_message_recive: HTTPSConnectionPool(host='ihsancrm.com', port=443): Max retries exceeded with url: /api/ihsanai/faceAi/receive (Caused by NewConnectionError('<urllib3.connection.HTTPSConnection object at 0x000001D2E380D480>: Failed to establish a new connection: [Errno 11002] getaddrinfo failed'))
2024-10-09 10:22:32 AM | ERROR | Exception in ihsan_ai_bot: HTTPSConnectionPool(host='bot.ihsancrm.com', port=443): Max retries exceeded with url: /ihsanai/ask/query (Caused by NewConnectionError('<urllib3.connection.HTTPSConnection object at 0x000001D2E380C610>: Failed to establish a new connection: [Errno 11002] getaddrinfo failed'))
2024-10-09 10:22:35 AM | ERROR | Exception in track_message_recive: HTTPSConnectionPool(host='ihsancrm.com', port=443): Max retries exceeded with url: /api/ihsanai/faceAi/receive (Caused by NewConnectionError('<urllib3.connection.HTTPSConnection object at 0x000001D2E380D750>: Failed to establish a new connection: [Errno 11002] getaddrinfo failed'))
2024-10-09 10:22:35 AM | ERROR | Exception in ihsan_ai_bot: HTTPSConnectionPool(host='bot.ihsancrm.com', port=443): Max retries exceeded with url: /ihsanai/ask/query (Caused by NewConnectionError('<urllib3.connection.HTTPSConnection object at 0x000001D2E380C8B0>: Failed to establish a new connection: [Errno 11002] getaddrinfo failed'))
2024-10-09 10:22:37 AM | ERROR | Exception in track_message_recive: HTTPSConnectionPool(host='ihsancrm.com', port=443): Max retries exceeded with url: /api/ihsanai/faceAi/receive (Caused by NewConnectionError('<urllib3.connection.HTTPSConnection object at 0x000001D2E380D6C0>: Failed to establish a new connection: [Errno 11002] getaddrinfo failed'))
2024-10-09 10:22:37 AM | ERROR | Exception in ihsan_ai_bot: HTTPSConnectionPool(host='bot.ihsancrm.com', port=443): Max retries exceeded with url: /ihsanai/ask/query (Caused by NewConnectionError('<urllib3.connection.HTTPSConnection object at 0x000001D2E380C3D0>: Failed to establish a new connection: [Errno 11002] getaddrinfo failed'))
2024-10-09 10:22:40 AM | ERROR | Exception in track_message_recive: HTTPSConnectionPool(host='ihsancrm.com', port=443): Max retries exceeded with url: /api/ihsanai/faceAi/receive (Caused by NewConnectionError('<urllib3.connection.HTTPSConnection object at 0x000001D2E380C5B0>: Failed to establish a new connection: [Errno 11002] getaddrinfo failed'))
2024-10-09 10:22:41 AM | ERROR | Exception in ihsan_ai_bot: HTTPSConnectionPool(host='bot.ihsancrm.com', port=443): Max retries exceeded with url: /ihsanai/ask/query (Caused by NewConnectionError('<urllib3.connection.HTTPSConnection object at 0x000001D2E380C0D0>: Failed to establish a new connection: [Errno 11002] getaddrinfo failed'))
2024-10-09 10:22:43 AM | ERROR | Exception in track_message_recive: HTTPSConnectionPool(host='ihsancrm.com', port=443): Max retries exceeded with url: /api/ihsanai/faceAi/receive (Caused by NewConnectionError('<urllib3.connection.HTTPSConnection object at 0x000001D2E380C550>: Failed to establish a new connection: [Errno 11002] getaddrinfo failed'))
2024-10-09 10:22:43 AM | ERROR | Exception in ihsan_ai_bot: HTTPSConnectionPool(host='bot.ihsancrm.com', port=443): Max retries exceeded with url: /ihsanai/ask/query (Caused by NewConnectionError('<urllib3.connection.HTTPSConnection object at 0x000001D2E380C880>: Failed to establish a new connection: [Errno 11002] getaddrinfo failed'))
2024-10-09 10:22:49 AM | ERROR | Exception in track_message_recive: HTTPSConnectionPool(host='ihsancrm.com', port=443): Max retries exceeded with url: /api/ihsanai/faceAi/receive (Caused by NewConnectionError('<urllib3.connection.HTTPSConnection object at 0x000001D2E380CC70>: Failed to establish a new connection: [Errno 11002] getaddrinfo failed'))
2024-10-09 10:23:00 AM | ERROR | Exception in ihsan_ai_bot: HTTPSConnectionPool(host='bot.ihsancrm.com', port=443): Max retries exceeded with url: /ihsanai/ask/query (Caused by NewConnectionError('<urllib3.connection.HTTPSConnection object at 0x000001D2E380C9D0>: Failed to establish a new connection: [Errno 11001] getaddrinfo failed'))
2024-10-09 10:23:02 AM | ERROR | Exception in track_message_recive: HTTPSConnectionPool(host='ihsancrm.com', port=443): Max retries exceeded with url: /api/ihsanai/faceAi/receive (Caused by NewConnectionError('<urllib3.connection.HTTPSConnection object at 0x000001D2E380CC40>: Failed to establish a new connection: [Errno 11002] getaddrinfo failed'))
2024-10-09 10:23:06 AM | ERROR | Exception in ihsan_ai_bot: HTTPSConnectionPool(host='bot.ihsancrm.com', port=443): Max retries exceeded with url: /ihsanai/ask/query (Caused by NewConnectionError('<urllib3.connection.HTTPSConnection object at 0x000001D2E380D5D0>: Failed to establish a new connection: [Errno 11002] getaddrinfo failed'))
2024-10-09 10:23:09 AM | ERROR | Exception in track_message_recive: HTTPSConnectionPool(host='ihsancrm.com', port=443): Max retries exceeded with url: /api/ihsanai/faceAi/receive (Caused by NewConnectionError('<urllib3.connection.HTTPSConnection object at 0x000001D2E380D600>: Failed to establish a new connection: [Errno 11002] getaddrinfo failed'))
2024-10-09 10:23:09 AM | ERROR | Exception in ihsan_ai_bot: HTTPSConnectionPool(host='bot.ihsancrm.com', port=443): Max retries exceeded with url: /ihsanai/ask/query (Caused by NewConnectionError('<urllib3.connection.HTTPSConnection object at 0x000001D2E380C6A0>: Failed to establish a new connection: [Errno 11002] getaddrinfo failed'))
2024-10-09 10:23:11 AM | ERROR | Exception in track_message_recive: HTTPSConnectionPool(host='ihsancrm.com', port=443): Max retries exceeded with url: /api/ihsanai/faceAi/receive (Caused by NewConnectionError('<urllib3.connection.HTTPSConnection object at 0x000001D2E380D540>: Failed to establish a new connection: [Errno 11002] getaddrinfo failed'))
2024-10-09 10:23:11 AM | ERROR | Exception in ihsan_ai_bot: HTTPSConnectionPool(host='bot.ihsancrm.com', port=443): Max retries exceeded with url: /ihsanai/ask/query (Caused by NewConnectionError('<urllib3.connection.HTTPSConnection object at 0x000001D2E380C670>: Failed to establish a new connection: [Errno 11002] getaddrinfo failed'))
2024-10-09 10:23:14 AM | ERROR | Exception in track_message_recive: HTTPSConnectionPool(host='ihsancrm.com', port=443): Max retries exceeded with url: /api/ihsanai/faceAi/receive (Caused by NewConnectionError('<urllib3.connection.HTTPSConnection object at 0x000001D2E380D840>: Failed to establish a new connection: [Errno 11002] getaddrinfo failed'))
2024-10-09 10:23:22 AM | ERROR | Exception in ihsan_ai_bot: HTTPSConnectionPool(host='bot.ihsancrm.com', port=443): Max retries exceeded with url: /ihsanai/ask/query (Caused by NewConnectionError('<urllib3.connection.HTTPSConnection object at 0x000001D2E380CA60>: Failed to establish a new connection: [Errno 11002] getaddrinfo failed'))
2024-10-09 10:23:25 AM | ERROR | Exception in track_message_recive: HTTPSConnectionPool(host='ihsancrm.com', port=443): Max retries exceeded with url: /api/ihsanai/faceAi/receive (Caused by NewConnectionError('<urllib3.connection.HTTPSConnection object at 0x000001D2E380CA30>: Failed to establish a new connection: [Errno 11002] getaddrinfo failed'))
2024-10-09 10:23:25 AM | ERROR | Exception in ihsan_ai_bot: HTTPSConnectionPool(host='bot.ihsancrm.com', port=443): Max retries exceeded with url: /ihsanai/ask/query (Caused by NewConnectionError('<urllib3.connection.HTTPSConnection object at 0x000001D2E380CDF0>: Failed to establish a new connection: [Errno 11002] getaddrinfo failed'))
2024-10-09 10:23:27 AM | ERROR | Exception in track_message_recive: HTTPSConnectionPool(host='ihsancrm.com', port=443): Max retries exceeded with url: /api/ihsanai/faceAi/receive (Caused by NewConnectionError('<urllib3.connection.HTTPSConnection object at 0x000001D2E380D5A0>: Failed to establish a new connection: [Errno 11002] getaddrinfo failed'))
2024-10-09 10:23:27 AM | ERROR | Exception in ihsan_ai_bot: HTTPSConnectionPool(host='bot.ihsancrm.com', port=443): Max retries exceeded with url: /ihsanai/ask/query (Caused by NewConnectionError('<urllib3.connection.HTTPSConnection object at 0x000001D2E380C6D0>: Failed to establish a new connection: [Errno 11002] getaddrinfo failed'))
2024-10-09 10:23:31 AM | ERROR | Exception in track_message_recive: HTTPSConnectionPool(host='ihsancrm.com', port=443): Max retries exceeded with url: /api/ihsanai/faceAi/receive (Caused by NewConnectionError('<urllib3.connection.HTTPSConnection object at 0x000001D2E380D7B0>: Failed to establish a new connection: [Errno 11002] getaddrinfo failed'))
2024-10-09 10:23:32 AM | ERROR | Exception in ihsan_ai_bot: HTTPSConnectionPool(host='bot.ihsancrm.com', port=443): Max retries exceeded with url: /ihsanai/ask/query (Caused by NewConnectionError('<urllib3.connection.HTTPSConnection object at 0x000001D2E380C970>: Failed to establish a new connection: [Errno 11002] getaddrinfo failed'))
2024-10-09 10:23:35 AM | ERROR | Exception in track_message_recive: HTTPSConnectionPool(host='ihsancrm.com', port=443): Max retries exceeded with url: /api/ihsanai/faceAi/receive (Caused by NewConnectionError('<urllib3.connection.HTTPSConnection object at 0x000001D2E380D720>: Failed to establish a new connection: [Errno 11002] getaddrinfo failed'))
2024-10-09 10:23:35 AM | ERROR | Exception in ihsan_ai_bot: HTTPSConnectionPool(host='bot.ihsancrm.com', port=443): Max retries exceeded with url: /ihsanai/ask/query (Caused by NewConnectionError('<urllib3.connection.HTTPSConnection object at 0x000001D2E380C610>: Failed to establish a new connection: [Errno 11002] getaddrinfo failed'))
2024-10-09 10:23:37 AM | ERROR | Exception in track_message_recive: HTTPSConnectionPool(host='ihsancrm.com', port=443): Max retries exceeded with url: /api/ihsanai/faceAi/receive (Caused by NewConnectionError('<urllib3.connection.HTTPSConnection object at 0x000001D2E380D6F0>: Failed to establish a new connection: [Errno 11002] getaddrinfo failed'))
2024-10-09 10:23:39 AM | ERROR | Exception in ihsan_ai_bot: HTTPSConnectionPool(host='bot.ihsancrm.com', port=443): Max retries exceeded with url: /ihsanai/ask/query (Caused by NewConnectionError('<urllib3.connection.HTTPSConnection object at 0x000001D2E380C8B0>: Failed to establish a new connection: [Errno 11002] getaddrinfo failed'))
2024-10-09 10:23:42 AM | ERROR | Exception in track_message_recive: HTTPSConnectionPool(host='ihsancrm.com', port=443): Max retries exceeded with url: /api/ihsanai/faceAi/receive (Caused by NewConnectionError('<urllib3.connection.HTTPSConnection object at 0x000001D2E380D630>: Failed to establish a new connection: [Errno 11002] getaddrinfo failed'))
2024-10-09 10:23:43 AM | ERROR | Exception in ihsan_ai_bot: HTTPSConnectionPool(host='bot.ihsancrm.com', port=443): Max retries exceeded with url: /ihsanai/ask/query (Caused by NewConnectionError('<urllib3.connection.HTTPSConnection object at 0x000001D2E380C3D0>: Failed to establish a new connection: [Errno 11002] getaddrinfo failed'))
2024-10-09 10:23:45 AM | ERROR | Exception in track_message_recive: HTTPSConnectionPool(host='ihsancrm.com', port=443): Max retries exceeded with url: /api/ihsanai/faceAi/receive (Caused by NewConnectionError('<urllib3.connection.HTTPSConnection object at 0x000001D2E380CF10>: Failed to establish a new connection: [Errno 11002] getaddrinfo failed'))
2024-10-09 10:23:45 AM | ERROR | Exception in ihsan_ai_bot: HTTPSConnectionPool(host='bot.ihsancrm.com', port=443): Max retries exceeded with url: /ihsanai/ask/query (Caused by NewConnectionError('<urllib3.connection.HTTPSConnection object at 0x000001D2E380C0D0>: Failed to establish a new connection: [Errno 11002] getaddrinfo failed'))
2024-10-09 10:23:48 AM | ERROR | Exception in track_message_recive: HTTPSConnectionPool(host='ihsancrm.com', port=443): Max retries exceeded with url: /api/ihsanai/faceAi/receive (Caused by NewConnectionError('<urllib3.connection.HTTPSConnection object at 0x000001D2E380D810>: Failed to establish a new connection: [Errno 11002] getaddrinfo failed'))
2024-10-09 10:23:48 AM | ERROR | Exception in ihsan_ai_bot: HTTPSConnectionPool(host='bot.ihsancrm.com', port=443): Max retries exceeded with url: /ihsanai/ask/query (Caused by NewConnectionError('<urllib3.connection.HTTPSConnection object at 0x000001D2E380C880>: Failed to establish a new connection: [Errno 11002] getaddrinfo failed'))
2024-10-09 10:23:50 AM | ERROR | Exception in track_message_recive: HTTPSConnectionPool(host='ihsancrm.com', port=443): Max retries exceeded with url: /api/ihsanai/faceAi/receive (Caused by NewConnectionError('<urllib3.connection.HTTPSConnection object at 0x000001D2E380D660>: Failed to establish a new connection: [Errno 11002] getaddrinfo failed'))
2024-10-09 10:23:50 AM | ERROR | Exception in ihsan_ai_bot: HTTPSConnectionPool(host='bot.ihsancrm.com', port=443): Max retries exceeded with url: /ihsanai/ask/query (Caused by NewConnectionError('<urllib3.connection.HTTPSConnection object at 0x000001D2E380C9D0>: Failed to establish a new connection: [Errno 11002] getaddrinfo failed'))
2024-10-09 10:23:53 AM | ERROR | Exception in track_message_recive: HTTPSConnectionPool(host='ihsancrm.com', port=443): Max retries exceeded with url: /api/ihsanai/faceAi/receive (Caused by NewConnectionError('<urllib3.connection.HTTPSConnection object at 0x000001D2E380D870>: Failed to establish a new connection: [Errno 11002] getaddrinfo failed'))
2024-10-09 10:23:54 AM | ERROR | Exception in ihsan_ai_bot: HTTPSConnectionPool(host='bot.ihsancrm.com', port=443): Max retries exceeded with url: /ihsanai/ask/query (Caused by NewConnectionError('<urllib3.connection.HTTPSConnection object at 0x000001D2E380D5D0>: Failed to establish a new connection: [Errno 11002] getaddrinfo failed'))
2024-10-09 10:23:56 AM | ERROR | Exception in track_message_recive: HTTPSConnectionPool(host='ihsancrm.com', port=443): Max retries exceeded with url: /api/ihsanai/faceAi/receive (Caused by NewConnectionError('<urllib3.connection.HTTPSConnection object at 0x000001D2E380D690>: Failed to establish a new connection: [Errno 11002] getaddrinfo failed'))
2024-10-09 10:23:56 AM | ERROR | Exception in ihsan_ai_bot: HTTPSConnectionPool(host='bot.ihsancrm.com', port=443): Max retries exceeded with url: /ihsanai/ask/query (Caused by NewConnectionError('<urllib3.connection.HTTPSConnection object at 0x000001D2E380C6A0>: Failed to establish a new connection: [Errno 11002] getaddrinfo failed'))
2024-10-09 10:24:01 AM | ERROR | Exception in track_message_recive: HTTPSConnectionPool(host='ihsancrm.com', port=443): Max retries exceeded with url: /api/ihsanai/faceAi/receive (Caused by NewConnectionError('<urllib3.connection.HTTPSConnection object at 0x000001D2E380D4B0>: Failed to establish a new connection: [Errno 11002] getaddrinfo failed'))
2024-10-09 10:24:02 AM | ERROR | Exception in ihsan_ai_bot: HTTPSConnectionPool(host='bot.ihsancrm.com', port=443): Max retries exceeded with url: /ihsanai/ask/query (Caused by NewConnectionError('<urllib3.connection.HTTPSConnection object at 0x000001D2E380C670>: Failed to establish a new connection: [Errno 11002] getaddrinfo failed'))
2024-10-09 10:24:05 AM | ERROR | Exception in track_message_recive: HTTPSConnectionPool(host='ihsancrm.com', port=443): Max retries exceeded with url: /api/ihsanai/faceAi/receive (Caused by NewConnectionError('<urllib3.connection.HTTPSConnection object at 0x000001D2E380CEE0>: Failed to establish a new connection: [Errno 11002] getaddrinfo failed'))
2024-10-09 10:24:05 AM | ERROR | Exception in ihsan_ai_bot: HTTPSConnectionPool(host='bot.ihsancrm.com', port=443): Max retries exceeded with url: /ihsanai/ask/query (Caused by NewConnectionError('<urllib3.connection.HTTPSConnection object at 0x000001D2E380CA60>: Failed to establish a new connection: [Errno 11002] getaddrinfo failed'))
2024-10-09 10:24:07 AM | ERROR | Exception in track_message_recive: HTTPSConnectionPool(host='ihsancrm.com', port=443): Max retries exceeded with url: /api/ihsanai/faceAi/receive (Caused by NewConnectionError('<urllib3.connection.HTTPSConnection object at 0x000001D2E380CEB0>: Failed to establish a new connection: [Errno 11002] getaddrinfo failed'))
2024-10-09 10:24:09 AM | ERROR | Exception in ihsan_ai_bot: HTTPSConnectionPool(host='bot.ihsancrm.com', port=443): Max retries exceeded with url: /ihsanai/ask/query (Caused by NewConnectionError('<urllib3.connection.HTTPSConnection object at 0x000001D2E380CDF0>: Failed to establish a new connection: [Errno 11002] getaddrinfo failed'))
2024-10-09 10:24:22 AM | ERROR | Exception in track_message_recive: HTTPSConnectionPool(host='ihsancrm.com', port=443): Max retries exceeded with url: /api/ihsanai/faceAi/receive (Caused by NewConnectionError('<urllib3.connection.HTTPSConnection object at 0x000001D2E380D480>: Failed to establish a new connection: [Errno 11001] getaddrinfo failed'))
2024-10-09 10:24:23 AM | ERROR | Exception in ihsan_ai_bot: HTTPSConnectionPool(host='bot.ihsancrm.com', port=443): Max retries exceeded with url: /ihsanai/ask/query (Caused by NewConnectionError('<urllib3.connection.HTTPSConnection object at 0x000001D2E380C6D0>: Failed to establish a new connection: [Errno 11002] getaddrinfo failed'))
2024-10-09 10:24:27 AM | ERROR | Exception in track_message_recive: HTTPSConnectionPool(host='ihsancrm.com', port=443): Max retries exceeded with url: /api/ihsanai/faceAi/receive (Caused by NewConnectionError('<urllib3.connection.HTTPSConnection object at 0x000001D2E380D750>: Failed to establish a new connection: [Errno 11002] getaddrinfo failed'))
2024-10-09 10:24:30 AM | ERROR | Exception in ihsan_ai_bot: HTTPSConnectionPool(host='bot.ihsancrm.com', port=443): Max retries exceeded with url: /ihsanai/ask/query (Caused by NewConnectionError('<urllib3.connection.HTTPSConnection object at 0x000001D2E380C970>: Failed to establish a new connection: [Errno 11002] getaddrinfo failed'))
2024-10-09 10:24:33 AM | ERROR | Exception in track_message_recive: HTTPSConnectionPool(host='ihsancrm.com', port=443): Max retries exceeded with url: /api/ihsanai/faceAi/receive (Caused by NewConnectionError('<urllib3.connection.HTTPSConnection object at 0x000001D2E380D6C0>: Failed to establish a new connection: [Errno 11002] getaddrinfo failed'))
2024-10-09 10:24:34 AM | ERROR | Exception in ihsan_ai_bot: HTTPSConnectionPool(host='bot.ihsancrm.com', port=443): Max retries exceeded with url: /ihsanai/ask/query (Caused by NewConnectionError('<urllib3.connection.HTTPSConnection object at 0x000001D2E380C610>: Failed to establish a new connection: [Errno 11002] getaddrinfo failed'))
2024-10-09 10:24:36 AM | ERROR | Exception in track_message_recive: HTTPSConnectionPool(host='ihsancrm.com', port=443): Max retries exceeded with url: /api/ihsanai/faceAi/receive (Caused by NewConnectionError('<urllib3.connection.HTTPSConnection object at 0x000001D2E380D5A0>: Failed to establish a new connection: [Errno 11002] getaddrinfo failed'))
2024-10-09 10:24:36 AM | ERROR | Exception in ihsan_ai_bot: HTTPSConnectionPool(host='bot.ihsancrm.com', port=443): Max retries exceeded with url: /ihsanai/ask/query (Caused by NewConnectionError('<urllib3.connection.HTTPSConnection object at 0x000001D2E380C610>: Failed to establish a new connection: [Errno 11002] getaddrinfo failed'))
2024-10-09 10:24:39 AM | ERROR | Exception in track_message_recive: HTTPSConnectionPool(host='ihsancrm.com', port=443): Max retries exceeded with url: /api/ihsanai/faceAi/receive (Caused by NewConnectionError('<urllib3.connection.HTTPSConnection object at 0x000001D2E380D990>: Failed to establish a new connection: [Errno 11002] getaddrinfo failed'))
2024-10-09 10:24:39 AM | ERROR | Exception in ihsan_ai_bot: HTTPSConnectionPool(host='bot.ihsancrm.com', port=443): Max retries exceeded with url: /ihsanai/ask/query (Caused by NewConnectionError('<urllib3.connection.HTTPSConnection object at 0x000001D2E380CEE0>: Failed to establish a new connection: [Errno 11002] getaddrinfo failed'))
2024-10-09 10:24:41 AM | ERROR | Exception in track_message_recive: HTTPSConnectionPool(host='ihsancrm.com', port=443): Max retries exceeded with url: /api/ihsanai/faceAi/receive (Caused by NewConnectionError('<urllib3.connection.HTTPSConnection object at 0x000001D2E380CC70>: Failed to establish a new connection: [Errno 11002] getaddrinfo failed'))
2024-10-09 10:24:41 AM | ERROR | Exception in ihsan_ai_bot: HTTPSConnectionPool(host='bot.ihsancrm.com', port=443): Max retries exceeded with url: /ihsanai/ask/query (Caused by NewConnectionError('<urllib3.connection.HTTPSConnection object at 0x000001D2E380D870>: Failed to establish a new connection: [Errno 11002] getaddrinfo failed'))
2024-10-09 10:24:45 AM | ERROR | Exception in track_message_recive: HTTPSConnectionPool(host='ihsancrm.com', port=443): Max retries exceeded with url: /api/ihsanai/faceAi/receive (Caused by NewConnectionError('<urllib3.connection.HTTPSConnection object at 0x000001D2E380D9C0>: Failed to establish a new connection: [Errno 11002] getaddrinfo failed'))
2024-10-09 10:24:49 AM | ERROR | Exception in ihsan_ai_bot: HTTPSConnectionPool(host='bot.ihsancrm.com', port=443): Max retries exceeded with url: /ihsanai/ask/query (Caused by NewConnectionError('<urllib3.connection.HTTPSConnection object at 0x000001D2E380D750>: Failed to establish a new connection: [Errno 11002] getaddrinfo failed'))
2024-10-09 10:24:52 AM | ERROR | Exception in track_message_recive: HTTPSConnectionPool(host='ihsancrm.com', port=443): Max retries exceeded with url: /api/ihsanai/faceAi/receive (Caused by NewConnectionError('<urllib3.connection.HTTPSConnection object at 0x000001D2E380D540>: Failed to establish a new connection: [Errno 11002] getaddrinfo failed'))
2024-10-09 10:24:52 AM | ERROR | Exception in ihsan_ai_bot: HTTPSConnectionPool(host='bot.ihsancrm.com', port=443): Max retries exceeded with url: /ihsanai/ask/query (Caused by NewConnectionError('<urllib3.connection.HTTPSConnection object at 0x000001D2E380D630>: Failed to establish a new connection: [Errno 11002] getaddrinfo failed'))
2024-10-09 10:24:54 AM | ERROR | Exception in track_message_recive: HTTPSConnectionPool(host='ihsancrm.com', port=443): Max retries exceeded with url: /api/ihsanai/faceAi/receive (Caused by NewConnectionError('<urllib3.connection.HTTPSConnection object at 0x000001D2E380D900>: Failed to establish a new connection: [Errno 11002] getaddrinfo failed'))
2024-10-09 10:24:54 AM | ERROR | Exception in ihsan_ai_bot: HTTPSConnectionPool(host='bot.ihsancrm.com', port=443): Max retries exceeded with url: /ihsanai/ask/query (Caused by NewConnectionError('<urllib3.connection.HTTPSConnection object at 0x000001D2E380CD60>: Failed to establish a new connection: [Errno 11002] getaddrinfo failed'))
2024-10-09 10:25:00 AM | ERROR | Exception in track_message_recive: HTTPSConnectionPool(host='ihsancrm.com', port=443): Max retries exceeded with url: /api/ihsanai/faceAi/receive (Caused by NewConnectionError('<urllib3.connection.HTTPSConnection object at 0x000001D2E380D810>: Failed to establish a new connection: [Errno 11002] getaddrinfo failed'))
2024-10-09 10:25:01 AM | ERROR | Exception in ihsan_ai_bot: HTTPSConnectionPool(host='bot.ihsancrm.com', port=443): Max retries exceeded with url: /ihsanai/ask/query (Caused by NewConnectionError('<urllib3.connection.HTTPSConnection object at 0x000001D2E380D720>: Failed to establish a new connection: [Errno 11002] getaddrinfo failed'))
2024-10-09 10:25:03 AM | ERROR | Exception in track_message_recive: HTTPSConnectionPool(host='ihsancrm.com', port=443): Max retries exceeded with url: /api/ihsanai/faceAi/receive (Caused by NewConnectionError('<urllib3.connection.HTTPSConnection object at 0x000001D2E380DAB0>: Failed to establish a new connection: [Errno 11002] getaddrinfo failed'))
2024-10-09 10:25:03 AM | ERROR | Exception in ihsan_ai_bot: HTTPSConnectionPool(host='bot.ihsancrm.com', port=443): Max retries exceeded with url: /ihsanai/ask/query (Caused by NewConnectionError('<urllib3.connection.HTTPSConnection object at 0x000001D2E380CA60>: Failed to establish a new connection: [Errno 11002] getaddrinfo failed'))
2024-10-09 10:25:05 AM | ERROR | Exception in track_message_recive: HTTPSConnectionPool(host='ihsancrm.com', port=443): Max retries exceeded with url: /api/ihsanai/faceAi/receive (Caused by NewConnectionError('<urllib3.connection.HTTPSConnection object at 0x000001D2E380DC60>: Failed to establish a new connection: [Errno 11002] getaddrinfo failed'))
2024-10-09 10:25:07 AM | ERROR | Exception in ihsan_ai_bot: HTTPSConnectionPool(host='bot.ihsancrm.com', port=443): Max retries exceeded with url: /ihsanai/ask/query (Caused by NewConnectionError('<urllib3.connection.HTTPSConnection object at 0x000001D2E380D900>: Failed to establish a new connection: [Errno 11002] getaddrinfo failed'))
2024-10-09 10:25:10 AM | ERROR | Exception in track_message_recive: HTTPSConnectionPool(host='ihsancrm.com', port=443): Max retries exceeded with url: /api/ihsanai/faceAi/receive (Caused by NewConnectionError('<urllib3.connection.HTTPSConnection object at 0x000001D2E380DAE0>: Failed to establish a new connection: [Errno 11002] getaddrinfo failed'))
2024-10-09 10:25:10 AM | ERROR | Exception in ihsan_ai_bot: HTTPSConnectionPool(host='bot.ihsancrm.com', port=443): Max retries exceeded with url: /ihsanai/ask/query (Caused by NewConnectionError('<urllib3.connection.HTTPSConnection object at 0x000001D2E380D8A0>: Failed to establish a new connection: [Errno 11002] getaddrinfo failed'))
2024-10-09 10:25:12 AM | ERROR | Exception in track_message_recive: HTTPSConnectionPool(host='ihsancrm.com', port=443): Max retries exceeded with url: /api/ihsanai/faceAi/receive (Caused by NewConnectionError('<urllib3.connection.HTTPSConnection object at 0x000001D2E380D810>: Failed to establish a new connection: [Errno 11002] getaddrinfo failed'))
2024-10-09 10:25:13 AM | ERROR | Exception in ihsan_ai_bot: HTTPSConnectionPool(host='bot.ihsancrm.com', port=443): Max retries exceeded with url: /ihsanai/ask/query (Caused by NewConnectionError('<urllib3.connection.HTTPSConnection object at 0x000001D2E380CC70>: Failed to establish a new connection: [Errno 11002] getaddrinfo failed'))
2024-10-09 10:25:15 AM | ERROR | Exception in track_message_recive: HTTPSConnectionPool(host='ihsancrm.com', port=443): Max retries exceeded with url: /api/ihsanai/faceAi/receive (Caused by NewConnectionError('<urllib3.connection.HTTPSConnection object at 0x000001D2E380D9F0>: Failed to establish a new connection: [Errno 11002] getaddrinfo failed'))
2024-10-09 10:25:15 AM | ERROR | Exception in ihsan_ai_bot: HTTPSConnectionPool(host='bot.ihsancrm.com', port=443): Max retries exceeded with url: /ihsanai/ask/query (Caused by NewConnectionError('<urllib3.connection.HTTPSConnection object at 0x000001D2E380CBE0>: Failed to establish a new connection: [Errno 11002] getaddrinfo failed'))
2024-10-09 10:25:17 AM | ERROR | Exception in track_message_recive: HTTPSConnectionPool(host='ihsancrm.com', port=443): Max retries exceeded with url: /api/ihsanai/faceAi/receive (Caused by NewConnectionError('<urllib3.connection.HTTPSConnection object at 0x000001D2E380DBA0>: Failed to establish a new connection: [Errno 11002] getaddrinfo failed'))
2024-10-09 10:25:18 AM | ERROR | Exception in ihsan_ai_bot: HTTPSConnectionPool(host='bot.ihsancrm.com', port=443): Max retries exceeded with url: /ihsanai/ask/query (Caused by NewConnectionError('<urllib3.connection.HTTPSConnection object at 0x000001D2E380DA80>: Failed to establish a new connection: [Errno 11002] getaddrinfo failed'))
2024-10-09 10:25:21 AM | ERROR | Exception in track_message_recive: HTTPSConnectionPool(host='ihsancrm.com', port=443): Max retries exceeded with url: /api/ihsanai/faceAi/receive (Caused by NewConnectionError('<urllib3.connection.HTTPSConnection object at 0x000001D2E380DC90>: Failed to establish a new connection: [Errno 11002] getaddrinfo failed'))
2024-10-09 10:25:21 AM | ERROR | Exception in ihsan_ai_bot: HTTPSConnectionPool(host='bot.ihsancrm.com', port=443): Max retries exceeded with url: /ihsanai/ask/query (Caused by NewConnectionError('<urllib3.connection.HTTPSConnection object at 0x000001D2E380CCD0>: Failed to establish a new connection: [Errno 11002] getaddrinfo failed'))
2024-10-09 10:25:23 AM | ERROR | Exception in track_message_recive: HTTPSConnectionPool(host='ihsancrm.com', port=443): Max retries exceeded with url: /api/ihsanai/faceAi/receive (Caused by NewConnectionError('<urllib3.connection.HTTPSConnection object at 0x000001D2E380C0D0>: Failed to establish a new connection: [Errno 11002] getaddrinfo failed'))
2024-10-09 10:25:23 AM | ERROR | Exception in ihsan_ai_bot: HTTPSConnectionPool(host='bot.ihsancrm.com', port=443): Max retries exceeded with url: /ihsanai/ask/query (Caused by NewConnectionError('<urllib3.connection.HTTPSConnection object at 0x000001D2E380D7B0>: Failed to establish a new connection: [Errno 11002] getaddrinfo failed'))
2024-10-09 10:25:26 AM | ERROR | Exception in track_message_recive: HTTPSConnectionPool(host='ihsancrm.com', port=443): Max retries exceeded with url: /api/ihsanai/faceAi/receive (Caused by NewConnectionError('<urllib3.connection.HTTPSConnection object at 0x000001D2E380D810>: Failed to establish a new connection: [Errno 11002] getaddrinfo failed'))
2024-10-09 10:25:26 AM | ERROR | Exception in ihsan_ai_bot: HTTPSConnectionPool(host='bot.ihsancrm.com', port=443): Max retries exceeded with url: /ihsanai/ask/query (Caused by NewConnectionError('<urllib3.connection.HTTPSConnection object at 0x000001D2E380D8D0>: Failed to establish a new connection: [Errno 11002] getaddrinfo failed'))
2024-10-09 10:25:28 AM | ERROR | Exception in track_message_recive: HTTPSConnectionPool(host='ihsancrm.com', port=443): Max retries exceeded with url: /api/ihsanai/faceAi/receive (Caused by NewConnectionError('<urllib3.connection.HTTPSConnection object at 0x000001D2E380CBE0>: Failed to establish a new connection: [Errno 11002] getaddrinfo failed'))
2024-10-09 10:25:29 AM | ERROR | Exception in ihsan_ai_bot: HTTPSConnectionPool(host='bot.ihsancrm.com', port=443): Max retries exceeded with url: /ihsanai/ask/query (Caused by NewConnectionError('<urllib3.connection.HTTPSConnection object at 0x000001D2E380CC70>: Failed to establish a new connection: [Errno 11002] getaddrinfo failed'))
2024-10-09 10:25:32 AM | ERROR | Exception in track_message_recive: HTTPSConnectionPool(host='ihsancrm.com', port=443): Max retries exceeded with url: /api/ihsanai/faceAi/receive (Caused by NewConnectionError('<urllib3.connection.HTTPSConnection object at 0x000001D2E380C9A0>: Failed to establish a new connection: [Errno 11002] getaddrinfo failed'))
2024-10-09 10:25:32 AM | ERROR | Exception in ihsan_ai_bot: HTTPSConnectionPool(host='bot.ihsancrm.com', port=443): Max retries exceeded with url: /ihsanai/ask/query (Caused by NewConnectionError('<urllib3.connection.HTTPSConnection object at 0x000001D2E380CD60>: Failed to establish a new connection: [Errno 11002] getaddrinfo failed'))
2024-10-09 10:25:34 AM | ERROR | Exception in track_message_recive: HTTPSConnectionPool(host='ihsancrm.com', port=443): Max retries exceeded with url: /api/ihsanai/faceAi/receive (Caused by NewConnectionError('<urllib3.connection.HTTPSConnection object at 0x000001D2E380D990>: Failed to establish a new connection: [Errno 11002] getaddrinfo failed'))
2024-10-09 10:25:34 AM | ERROR | Exception in ihsan_ai_bot: HTTPSConnectionPool(host='bot.ihsancrm.com', port=443): Max retries exceeded with url: /ihsanai/ask/query (Caused by NewConnectionError('<urllib3.connection.HTTPSConnection object at 0x000001D2E380D750>: Failed to establish a new connection: [Errno 11002] getaddrinfo failed'))
2024-10-09 10:25:40 AM | ERROR | Exception in track_message_recive: HTTPSConnectionPool(host='ihsancrm.com', port=443): Max retries exceeded with url: /api/ihsanai/faceAi/receive (Caused by NewConnectionError('<urllib3.connection.HTTPSConnection object at 0x000001D2E380D9F0>: Failed to establish a new connection: [Errno 11002] getaddrinfo failed'))
2024-10-09 10:25:48 AM | ERROR | Exception in ihsan_ai_bot: HTTPSConnectionPool(host='bot.ihsancrm.com', port=443): Max retries exceeded with url: /ihsanai/ask/query (Caused by NewConnectionError('<urllib3.connection.HTTPSConnection object at 0x000001D2E380C5B0>: Failed to establish a new connection: [Errno 11002] getaddrinfo failed'))
2024-10-09 10:25:51 AM | ERROR | Exception in track_message_recive: HTTPSConnectionPool(host='ihsancrm.com', port=443): Max retries exceeded with url: /api/ihsanai/faceAi/receive (Caused by NewConnectionError('<urllib3.connection.HTTPSConnection object at 0x000001D2E380DAB0>: Failed to establish a new connection: [Errno 11002] getaddrinfo failed'))
2024-10-09 10:25:51 AM | ERROR | Exception in ihsan_ai_bot: HTTPSConnectionPool(host='bot.ihsancrm.com', port=443): Max retries exceeded with url: /ihsanai/ask/query (Caused by NewConnectionError('<urllib3.connection.HTTPSConnection object at 0x000001D2E380D480>: Failed to establish a new connection: [Errno 11002] getaddrinfo failed'))
2024-10-09 10:25:53 AM | ERROR | Exception in track_message_recive: HTTPSConnectionPool(host='ihsancrm.com', port=443): Max retries exceeded with url: /api/ihsanai/faceAi/receive (Caused by NewConnectionError('<urllib3.connection.HTTPSConnection object at 0x000001D2E380C910>: Failed to establish a new connection: [Errno 11002] getaddrinfo failed'))
2024-10-09 10:25:53 AM | ERROR | Exception in ihsan_ai_bot: HTTPSConnectionPool(host='bot.ihsancrm.com', port=443): Max retries exceeded with url: /ihsanai/ask/query (Caused by NewConnectionError('<urllib3.connection.HTTPSConnection object at 0x000001D2E380D540>: Failed to establish a new connection: [Errno 11002] getaddrinfo failed'))
2024-10-09 10:25:56 AM | ERROR | Exception in track_message_recive: HTTPSConnectionPool(host='ihsancrm.com', port=443): Max retries exceeded with url: /api/ihsanai/faceAi/receive (Caused by NewConnectionError('<urllib3.connection.HTTPSConnection object at 0x000001D2E380CC40>: Failed to establish a new connection: [Errno 11002] getaddrinfo failed'))
2024-10-09 10:25:57 AM | ERROR | Exception in ihsan_ai_bot: HTTPSConnectionPool(host='bot.ihsancrm.com', port=443): Max retries exceeded with url: /ihsanai/ask/query (Caused by NewConnectionError('<urllib3.connection.HTTPSConnection object at 0x000001D2E380CA60>: Failed to establish a new connection: [Errno 11002] getaddrinfo failed'))
2024-10-09 10:25:59 AM | ERROR | Exception in track_message_recive: HTTPSConnectionPool(host='ihsancrm.com', port=443): Max retries exceeded with url: /api/ihsanai/faceAi/receive (Caused by NewConnectionError('<urllib3.connection.HTTPSConnection object at 0x000001D2E380D600>: Failed to establish a new connection: [Errno 11002] getaddrinfo failed'))
2024-10-09 10:25:59 AM | ERROR | Exception in ihsan_ai_bot: HTTPSConnectionPool(host='bot.ihsancrm.com', port=443): Max retries exceeded with url: /ihsanai/ask/query (Caused by NewConnectionError('<urllib3.connection.HTTPSConnection object at 0x000001D2E380DC30>: Failed to establish a new connection: [Errno 11002] getaddrinfo failed'))
2024-10-09 10:26:02 AM | ERROR | Exception in track_message_recive: HTTPSConnectionPool(host='ihsancrm.com', port=443): Max retries exceeded with url: /api/ihsanai/faceAi/receive (Caused by NewConnectionError('<urllib3.connection.HTTPSConnection object at 0x000001D2E380DCC0>: Failed to establish a new connection: [Errno 11002] getaddrinfo failed'))
2024-10-09 10:26:02 AM | ERROR | Exception in ihsan_ai_bot: HTTPSConnectionPool(host='bot.ihsancrm.com', port=443): Max retries exceeded with url: /ihsanai/ask/query (Caused by NewConnectionError('<urllib3.connection.HTTPSConnection object at 0x000001D2E380CBE0>: Failed to establish a new connection: [Errno 11002] getaddrinfo failed'))
2024-10-09 10:26:04 AM | ERROR | Exception in track_message_recive: HTTPSConnectionPool(host='ihsancrm.com', port=443): Max retries exceeded with url: /api/ihsanai/faceAi/receive (Caused by NewConnectionError('<urllib3.connection.HTTPSConnection object at 0x000001D2E380D600>: Failed to establish a new connection: [Errno 11002] getaddrinfo failed'))
2024-10-09 10:26:04 AM | ERROR | Exception in ihsan_ai_bot: HTTPSConnectionPool(host='bot.ihsancrm.com', port=443): Max retries exceeded with url: /ihsanai/ask/query (Caused by NewConnectionError('<urllib3.connection.HTTPSConnection object at 0x000001D2E380CD30>: Failed to establish a new connection: [Errno 11002] getaddrinfo failed'))
2024-10-09 10:26:07 AM | ERROR | Exception in track_message_recive: HTTPSConnectionPool(host='ihsancrm.com', port=443): Max retries exceeded with url: /api/ihsanai/faceAi/receive (Caused by NewConnectionError('<urllib3.connection.HTTPSConnection object at 0x000001D2E380C670>: Failed to establish a new connection: [Errno 11002] getaddrinfo failed'))
2024-10-09 10:26:08 AM | ERROR | Exception in ihsan_ai_bot: HTTPSConnectionPool(host='bot.ihsancrm.com', port=443): Max retries exceeded with url: /ihsanai/ask/query (Caused by NewConnectionError('<urllib3.connection.HTTPSConnection object at 0x000001D2E380D810>: Failed to establish a new connection: [Errno 11002] getaddrinfo failed'))
2024-10-09 10:26:10 AM | ERROR | Exception in track_message_recive: HTTPSConnectionPool(host='ihsancrm.com', port=443): Max retries exceeded with url: /api/ihsanai/faceAi/receive (Caused by NewConnectionError('<urllib3.connection.HTTPSConnection object at 0x000001D2E380C6D0>: Failed to establish a new connection: [Errno 11002] getaddrinfo failed'))
2024-10-09 10:26:10 AM | ERROR | Exception in ihsan_ai_bot: HTTPSConnectionPool(host='bot.ihsancrm.com', port=443): Max retries exceeded with url: /ihsanai/ask/query (Caused by NewConnectionError('<urllib3.connection.HTTPSConnection object at 0x000001D2E380D6C0>: Failed to establish a new connection: [Errno 11002] getaddrinfo failed'))
2024-10-09 10:26:12 AM | ERROR | Exception in track_message_recive: HTTPSConnectionPool(host='ihsancrm.com', port=443): Max retries exceeded with url: /api/ihsanai/faceAi/receive (Caused by NewConnectionError('<urllib3.connection.HTTPSConnection object at 0x000001D2E380C910>: Failed to establish a new connection: [Errno 11002] getaddrinfo failed'))
2024-10-09 10:26:13 AM | ERROR | Exception in ihsan_ai_bot: HTTPSConnectionPool(host='bot.ihsancrm.com', port=443): Max retries exceeded with url: /ihsanai/ask/query (Caused by NewConnectionError('<urllib3.connection.HTTPSConnection object at 0x000001D2E380D630>: Failed to establish a new connection: [Errno 11002] getaddrinfo failed'))
2024-10-09 10:26:15 AM | ERROR | Exception in track_message_recive: HTTPSConnectionPool(host='ihsancrm.com', port=443): Max retries exceeded with url: /api/ihsanai/faceAi/receive (Caused by NewConnectionError('<urllib3.connection.HTTPSConnection object at 0x000001D2E380DC90>: Failed to establish a new connection: [Errno 11002] getaddrinfo failed'))
2024-10-09 10:26:15 AM | ERROR | Exception in ihsan_ai_bot: HTTPSConnectionPool(host='bot.ihsancrm.com', port=443): Max retries exceeded with url: /ihsanai/ask/query (Caused by NewConnectionError('<urllib3.connection.HTTPSConnection object at 0x000001D2E380C9D0>: Failed to establish a new connection: [Errno 11002] getaddrinfo failed'))
2024-10-09 10:26:18 AM | ERROR | Exception in track_message_recive: HTTPSConnectionPool(host='ihsancrm.com', port=443): Max retries exceeded with url: /api/ihsanai/faceAi/receive (Caused by NewConnectionError('<urllib3.connection.HTTPSConnection object at 0x000001D2E380C9A0>: Failed to establish a new connection: [Errno 11002] getaddrinfo failed'))
2024-10-09 10:26:19 AM | ERROR | Exception in ihsan_ai_bot: HTTPSConnectionPool(host='bot.ihsancrm.com', port=443): Max retries exceeded with url: /ihsanai/ask/query (Caused by NewConnectionError('<urllib3.connection.HTTPSConnection object at 0x000001D2E380DB70>: Failed to establish a new connection: [Errno 11002] getaddrinfo failed'))
2024-10-09 10:26:21 AM | ERROR | Exception in track_message_recive: HTTPSConnectionPool(host='ihsancrm.com', port=443): Max retries exceeded with url: /api/ihsanai/faceAi/receive (Caused by NewConnectionError('<urllib3.connection.HTTPSConnection object at 0x000001D2E380C3D0>: Failed to establish a new connection: [Errno 11002] getaddrinfo failed'))
2024-10-09 10:26:21 AM | ERROR | Exception in ihsan_ai_bot: HTTPSConnectionPool(host='bot.ihsancrm.com', port=443): Max retries exceeded with url: /ihsanai/ask/query (Caused by NewConnectionError('<urllib3.connection.HTTPSConnection object at 0x000001D2E380D5D0>: Failed to establish a new connection: [Errno 11002] getaddrinfo failed'))
2024-10-09 10:26:24 AM | ERROR | Exception in track_message_recive: HTTPSConnectionPool(host='ihsancrm.com', port=443): Max retries exceeded with url: /api/ihsanai/faceAi/receive (Caused by NewConnectionError('<urllib3.connection.HTTPSConnection object at 0x000001D2E380DA80>: Failed to establish a new connection: [Errno 11002] getaddrinfo failed'))
2024-10-09 10:26:24 AM | ERROR | Exception in ihsan_ai_bot: HTTPSConnectionPool(host='bot.ihsancrm.com', port=443): Max retries exceeded with url: /ihsanai/ask/query (Caused by NewConnectionError('<urllib3.connection.HTTPSConnection object at 0x000001D2E380CF10>: Failed to establish a new connection: [Errno 11002] getaddrinfo failed'))
2024-10-09 10:26:26 AM | ERROR | Exception in track_message_recive: HTTPSConnectionPool(host='ihsancrm.com', port=443): Max retries exceeded with url: /api/ihsanai/faceAi/receive (Caused by NewConnectionError('<urllib3.connection.HTTPSConnection object at 0x000001D2E380CCD0>: Failed to establish a new connection: [Errno 11002] getaddrinfo failed'))
2024-10-09 10:26:26 AM | ERROR | Exception in ihsan_ai_bot: HTTPSConnectionPool(host='bot.ihsancrm.com', port=443): Max retries exceeded with url: /ihsanai/ask/query (Caused by NewConnectionError('<urllib3.connection.HTTPSConnection object at 0x000001D2E380D6F0>: Failed to establish a new connection: [Errno 11002] getaddrinfo failed'))
2024-10-09 10:26:29 AM | ERROR | Exception in track_message_recive: HTTPSConnectionPool(host='ihsancrm.com', port=443): Max retries exceeded with url: /api/ihsanai/faceAi/receive (Caused by NewConnectionError('<urllib3.connection.HTTPSConnection object at 0x000001D2E380D7B0>: Failed to establish a new connection: [Errno 11002] getaddrinfo failed'))
2024-10-09 10:26:30 AM | ERROR | Exception in ihsan_ai_bot: HTTPSConnectionPool(host='bot.ihsancrm.com', port=443): Max retries exceeded with url: /ihsanai/ask/query (Caused by NewConnectionError('<urllib3.connection.HTTPSConnection object at 0x000001D2E380DB40>: Failed to establish a new connection: [Errno 11002] getaddrinfo failed'))
2024-10-09 10:26:32 AM | ERROR | Exception in track_message_recive: HTTPSConnectionPool(host='ihsancrm.com', port=443): Max retries exceeded with url: /api/ihsanai/faceAi/receive (Caused by NewConnectionError('<urllib3.connection.HTTPSConnection object at 0x000001D2E380D8D0>: Failed to establish a new connection: [Errno 11002] getaddrinfo failed'))
2024-10-09 10:26:32 AM | ERROR | Exception in ihsan_ai_bot: HTTPSConnectionPool(host='bot.ihsancrm.com', port=443): Max retries exceeded with url: /ihsanai/ask/query (Caused by NewConnectionError('<urllib3.connection.HTTPSConnection object at 0x000001D2E380CEB0>: Failed to establish a new connection: [Errno 11002] getaddrinfo failed'))
2024-10-09 10:26:34 AM | ERROR | Exception in track_message_recive: HTTPSConnectionPool(host='ihsancrm.com', port=443): Max retries exceeded with url: /api/ihsanai/faceAi/receive (Caused by NewConnectionError('<urllib3.connection.HTTPSConnection object at 0x000001D2E380CC70>: Failed to establish a new connection: [Errno 11002] getaddrinfo failed'))
2024-10-09 10:26:35 AM | ERROR | Exception in ihsan_ai_bot: HTTPSConnectionPool(host='bot.ihsancrm.com', port=443): Max retries exceeded with url: /ihsanai/ask/query (Caused by NewConnectionError('<urllib3.connection.HTTPSConnection object at 0x000001D2E380DBA0>: Failed to establish a new connection: [Errno 11002] getaddrinfo failed'))
2024-10-09 10:26:37 AM | ERROR | Exception in track_message_recive: HTTPSConnectionPool(host='ihsancrm.com', port=443): Max retries exceeded with url: /api/ihsanai/faceAi/receive (Caused by NewConnectionError('<urllib3.connection.HTTPSConnection object at 0x000001D2E380CD60>: Failed to establish a new connection: [Errno 11002] getaddrinfo failed'))
2024-10-09 10:26:37 AM | ERROR | Exception in ihsan_ai_bot: HTTPSConnectionPool(host='bot.ihsancrm.com', port=443): Max retries exceeded with url: /ihsanai/ask/query (Caused by NewConnectionError('<urllib3.connection.HTTPSConnection object at 0x000001D2E380C8B0>: Failed to establish a new connection: [Errno 11002] getaddrinfo failed'))
2024-10-09 10:26:43 AM | ERROR | Exception in track_message_recive: HTTPSConnectionPool(host='ihsancrm.com', port=443): Max retries exceeded with url: /api/ihsanai/faceAi/receive (Caused by NewConnectionError('<urllib3.connection.HTTPSConnection object at 0x000001D2E380D750>: Failed to establish a new connection: [Errno 11002] getaddrinfo failed'))
2024-10-09 10:26:44 AM | ERROR | Exception in ihsan_ai_bot: HTTPSConnectionPool(host='bot.ihsancrm.com', port=443): Max retries exceeded with url: /ihsanai/ask/query (Caused by NewConnectionError('<urllib3.connection.HTTPSConnection object at 0x000001D2E380DA50>: Failed to establish a new connection: [Errno 11002] getaddrinfo failed'))
2024-10-09 10:26:46 AM | ERROR | Exception in track_message_recive: HTTPSConnectionPool(host='ihsancrm.com', port=443): Max retries exceeded with url: /api/ihsanai/faceAi/receive (Caused by NewConnectionError('<urllib3.connection.HTTPSConnection object at 0x000001D2E380C5B0>: Failed to establish a new connection: [Errno 11002] getaddrinfo failed'))
2024-10-09 10:26:46 AM | ERROR | Exception in ihsan_ai_bot: HTTPSConnectionPool(host='bot.ihsancrm.com', port=443): Max retries exceeded with url: /ihsanai/ask/query (Caused by NewConnectionError('<urllib3.connection.HTTPSConnection object at 0x000001D2E380CA30>: Failed to establish a new connection: [Errno 11002] getaddrinfo failed'))
2024-10-09 10:26:50 AM | ERROR | Exception in track_message_recive: HTTPSConnectionPool(host='ihsancrm.com', port=443): Max retries exceeded with url: /api/ihsanai/faceAi/receive (Caused by NewConnectionError('<urllib3.connection.HTTPSConnection object at 0x000001D2E380D480>: Failed to establish a new connection: [Errno 11002] getaddrinfo failed'))
2024-10-09 10:26:53 AM | ERROR | Exception in ihsan_ai_bot: HTTPSConnectionPool(host='bot.ihsancrm.com', port=443): Max retries exceeded with url: /ihsanai/ask/query (Caused by NewConnectionError('<urllib3.connection.HTTPSConnection object at 0x000001D2E380D9F0>: Failed to establish a new connection: [Errno 11002] getaddrinfo failed'))
2024-10-09 10:26:57 AM | ERROR | Exception in track_message_recive: HTTPSConnectionPool(host='ihsancrm.com', port=443): Max retries exceeded with url: /api/ihsanai/faceAi/receive (Caused by NewConnectionError('<urllib3.connection.HTTPSConnection object at 0x000001D2E380D540>: Failed to establish a new connection: [Errno 11002] getaddrinfo failed'))
2024-10-09 10:26:58 AM | ERROR | Exception in ihsan_ai_bot: HTTPSConnectionPool(host='bot.ihsancrm.com', port=443): Max retries exceeded with url: /ihsanai/ask/query (Caused by NewConnectionError('<urllib3.connection.HTTPSConnection object at 0x000001D2E380D930>: Failed to establish a new connection: [Errno 11002] getaddrinfo failed'))
2024-10-09 10:27:00 AM | ERROR | Exception in track_message_recive: HTTPSConnectionPool(host='ihsancrm.com', port=443): Max retries exceeded with url: /api/ihsanai/faceAi/receive (Caused by NewConnectionError('<urllib3.connection.HTTPSConnection object at 0x000001D2E380CA60>: Failed to establish a new connection: [Errno 11002] getaddrinfo failed'))
2024-10-09 10:27:00 AM | ERROR | Exception in ihsan_ai_bot: HTTPSConnectionPool(host='bot.ihsancrm.com', port=443): Max retries exceeded with url: /ihsanai/ask/query (Caused by NewConnectionError('<urllib3.connection.HTTPSConnection object at 0x000001D2E380DAB0>: Failed to establish a new connection: [Errno 11002] getaddrinfo failed'))
2024-10-09 10:40:25 AM | ERROR | Exception in track_message_recive: HTTPSConnectionPool(host='ihsancrm.com', port=443): Max retries exceeded with url: /api/ihsanai/faceAi/receive (Caused by NewConnectionError('<urllib3.connection.HTTPSConnection object at 0x000002AD6D4A5660>: Failed to establish a new connection: [Errno 11002] getaddrinfo failed'))
2024-10-09 10:40:26 AM | ERROR | Exception in ihsan_ai_bot: HTTPSConnectionPool(host='bot.ihsancrm.com', port=443): Max retries exceeded with url: /ihsanai/ask/query (Caused by NewConnectionError('<urllib3.connection.HTTPSConnection object at 0x000002AD6D4A4B20>: Failed to establish a new connection: [Errno 11002] getaddrinfo failed'))
2024-10-09 10:40:26 AM | ERROR | Exception in track_message_sent: HTTPSConnectionPool(host='ihsancrm.com', port=443): Max retries exceeded with url: /api/ihsanai/faceAi/sent (Caused by NewConnectionError('<urllib3.connection.HTTPSConnection object at 0x000002AD6D4A56F0>: Failed to establish a new connection: [Errno 11002] getaddrinfo failed'))
2024-10-09 10:40:46 AM | ERROR | Exception in track_message_recive: HTTPSConnectionPool(host='ihsancrm.com', port=443): Max retries exceeded with url: /api/ihsanai/faceAi/receive (Caused by NewConnectionError('<urllib3.connection.HTTPSConnection object at 0x000002AD6D4A5690>: Failed to establish a new connection: [Errno 11002] getaddrinfo failed'))
2024-10-09 10:40:47 AM | ERROR | Exception in ihsan_ai_bot: HTTPSConnectionPool(host='bot.ihsancrm.com', port=443): Max retries exceeded with url: /ihsanai/ask/query (Caused by NewConnectionError('<urllib3.connection.HTTPSConnection object at 0x000002AD6D4A55A0>: Failed to establish a new connection: [Errno 11002] getaddrinfo failed'))
2024-10-09 10:40:48 AM | ERROR | Exception in track_message_sent: HTTPSConnectionPool(host='ihsancrm.com', port=443): Max retries exceeded with url: /api/ihsanai/faceAi/sent (Caused by NewConnectionError('<urllib3.connection.HTTPSConnection object at 0x000002AD6D4A5900>: Failed to establish a new connection: [Errno 11002] getaddrinfo failed'))
2024-10-09 10:40:53 AM | ERROR | Exception in track_message_recive: HTTPSConnectionPool(host='ihsancrm.com', port=443): Max retries exceeded with url: /api/ihsanai/faceAi/receive (Caused by NewConnectionError('<urllib3.connection.HTTPSConnection object at 0x000002AD6D4A5690>: Failed to establish a new connection: [Errno 11002] getaddrinfo failed'))
2024-10-09 10:40:53 AM | ERROR | Exception in ihsan_ai_bot: HTTPSConnectionPool(host='bot.ihsancrm.com', port=443): Max retries exceeded with url: /ihsanai/ask/query (Caused by NewConnectionError('<urllib3.connection.HTTPSConnection object at 0x000002AD6D4A54B0>: Failed to establish a new connection: [Errno 11002] getaddrinfo failed'))
2024-10-09 10:40:54 AM | ERROR | Exception in track_message_sent: HTTPSConnectionPool(host='ihsancrm.com', port=443): Max retries exceeded with url: /api/ihsanai/faceAi/sent (Caused by NewConnectionError('<urllib3.connection.HTTPSConnection object at 0x000002AD6D4A58D0>: Failed to establish a new connection: [Errno 11002] getaddrinfo failed'))
2024-10-09 10:40:59 AM | ERROR | Exception in track_message_recive: HTTPSConnectionPool(host='ihsancrm.com', port=443): Max retries exceeded with url: /api/ihsanai/faceAi/receive (Caused by NewConnectionError('<urllib3.connection.HTTPSConnection object at 0x000002AD6D4A5660>: Failed to establish a new connection: [Errno 11002] getaddrinfo failed'))
2024-10-09 10:40:59 AM | ERROR | Exception in ihsan_ai_bot: HTTPSConnectionPool(host='bot.ihsancrm.com', port=443): Max retries exceeded with url: /ihsanai/ask/query (Caused by NewConnectionError('<urllib3.connection.HTTPSConnection object at 0x000002AD6D4A58A0>: Failed to establish a new connection: [Errno 11002] getaddrinfo failed'))
2024-10-09 10:41:00 AM | ERROR | Exception in track_message_sent: HTTPSConnectionPool(host='ihsancrm.com', port=443): Max retries exceeded with url: /api/ihsanai/faceAi/sent (Caused by NewConnectionError('<urllib3.connection.HTTPSConnection object at 0x000002AD6D4A5960>: Failed to establish a new connection: [Errno 11002] getaddrinfo failed'))
2024-10-09 10:41:02 AM | ERROR | Exception in track_message_recive: HTTPSConnectionPool(host='ihsancrm.com', port=443): Max retries exceeded with url: /api/ihsanai/faceAi/receive (Caused by NewConnectionError('<urllib3.connection.HTTPSConnection object at 0x000002AD6D4A5660>: Failed to establish a new connection: [Errno 11002] getaddrinfo failed'))
2024-10-09 10:41:02 AM | ERROR | Exception in ihsan_ai_bot: HTTPSConnectionPool(host='bot.ihsancrm.com', port=443): Max retries exceeded with url: /ihsanai/ask/query (Caused by NewConnectionError('<urllib3.connection.HTTPSConnection object at 0x000002AD6D4A56C0>: Failed to establish a new connection: [Errno 11002] getaddrinfo failed'))
2024-10-09 10:41:02 AM | ERROR | Exception in track_message_sent: HTTPSConnectionPool(host='ihsancrm.com', port=443): Max retries exceeded with url: /api/ihsanai/faceAi/sent (Caused by NewConnectionError('<urllib3.connection.HTTPSConnection object at 0x000002AD6D4A5840>: Failed to establish a new connection: [Errno 11002] getaddrinfo failed'))
2024-10-14 09:49:54 AM | ERROR | Exception in restore_a_session: [Errno 2] No such file or directory: '.sessions/.gitkeep/data.pkl'
2024-10-14 09:50:53 AM | ERROR | Exception in restore_a_session: [Errno 2] No such file or directory: '.sessions/.gitkeep/data.pkl'
2024-10-14 09:50:53 AM | ERROR | Exception in restore_a_session: Message: Unable to locate or obtain driver for chrome; For documentation on this error, please visit: https://www.selenium.dev/documentation/webdriver/troubleshooting/errors/driver_location

2024-10-14 09:54:00 AM | ERROR | Exception in restore_a_session: Message: Unable to locate or obtain driver for chrome; For documentation on this error, please visit: https://www.selenium.dev/documentation/webdriver/troubleshooting/errors/driver_location2024-10-14 09:54:56 AM | ERROR | Exception in restore_a_session: Message: Unable to locate or obtain driver for chrome; For documentation on this error, please visit: https://www.selenium.dev/documentation/webdriver/troubleshooting/errors/driver_location

2024-10-14 09:55:10 AM | ERROR | Exception in restore_a_session: Message: Unable to locate or obtain driver for chrome; For documentation on this error, please visit: https://www.selenium.dev/documentation/webdriver/troubleshooting/errors/driver_location

